Workbook

Sheet Summary
A1: ESTIMATE SUMMARY — BOTTOM LINE
A3: Project Name | B3: ='Project Info'!B4
A4: Estimate Number | B4: ='Project Info'!B3
A5: GC / Client | B5: ='Project Info'!B5
A6: Estimator | B6: ='Project Info'!B6
A7: Due Date | B7: ='Project Info'!B11
A9: COST BREAKDOWN (active scopes only)
A10: Material | C10: =Markups!D33
A11: Freight | C11: =Markups!E33
A12: Labor | C12: =Markups!F33
A13: Tax | C13: =Markups!H33
A14: Contingency | C14: =Markups!K33
A15: Escalation | C15: =Markups!M33
A16: Overhead | C16: =Markups!O33
A17: Fee | C17: =Markups!R33
A18: Bond / Insurance | C18: =Markups!U33
A19: Grand Total (pre-adjustment) | C19: =Markups!V33
A20: Adjustments | C20: =Markups!W33
A22: GRAND TOTAL (bottom line) | C22: =Markups!X33
A24: PER-SCOPE GRAND TOTALS
A25: Scope | B25: Active | C25: Grand Total | D25: % of Bottom Line
A26: =Markups!A13 | B26: =Markups!C13 | C26: =Markups!X13 | D26: =IFERROR(C26/Markups!X33,"")
A27: =Markups!A14 | B27: =Markups!C14 | C27: =Markups!X14 | D27: =IFERROR(C27/Markups!X33,"")
A28: =Markups!A15 | B28: =Markups!C15 | C28: =Markups!X15 | D28: =IFERROR(C28/Markups!X33,"")
A29: =Markups!A16 | B29: =Markups!C16 | C29: =Markups!X16 | D29: =IFERROR(C29/Markups!X33,"")
A30: =Markups!A17 | B30: =Markups!C17 | C30: =Markups!X17 | D30: =IFERROR(C30/Markups!X33,"")
A31: =Markups!A18 | B31: =Markups!C18 | C31: =Markups!X18 | D31: =IFERROR(C31/Markups!X33,"")
A32: =Markups!A19 | B32: =Markups!C19 | C32: =Markups!X19 | D32: =IFERROR(C32/Markups!X33,"")
A33: =Markups!A20 | B33: =Markups!C20 | C33: =Markups!X20 | D33: =IFERROR(C33/Markups!X33,"")
A34: =Markups!A21 | B34: =Markups!C21 | C34: =Markups!X21 | D34: =IFERROR(C34/Markups!X33,"")
A35: =Markups!A22 | B35: =Markups!C22 | C35: =Markups!X22 | D35: =IFERROR(C35/Markups!X33,"")
A36: =Markups!A23 | B36: =Markups!C23 | C36: =Markups!X23 | D36: =IFERROR(C36/Markups!X33,"")
A37: =Markups!A24 | B37: =Markups!C24 | C37: =Markups!X24 | D37: =IFERROR(C37/Markups!X33,"")
A38: =Markups!A25 | B38: =Markups!C25 | C38: =Markups!X25 | D38: =IFERROR(C38/Markups!X33,"")
A39: =Markups!A26 | B39: =Markups!C26 | C39: =Markups!X26 | D39: =IFERROR(C39/Markups!X33,"")
A40: =Markups!A27 | B40: =Markups!C27 | C40: =Markups!X27 | D40: =IFERROR(C40/Markups!X33,"")
A41: =Markups!A28 | B41: =Markups!C28 | C41: =Markups!X28 | D41: =IFERROR(C41/Markups!X33,"")
A42: =Markups!A29 | B42: =Markups!C29 | C42: =Markups!X29 | D42: =IFERROR(C42/Markups!X33,"")
A43: =Markups!A30 | B43: =Markups!C30 | C43: =Markups!X30 | D43: =IFERROR(C43/Markups!X33,"")
A44: =Markups!A31 | B44: =Markups!C31 | C44: =Markups!X31 | D44: =IFERROR(C44/Markups!X33,"")
...

Sheet Project Info
A1: PROJECT INFORMATION
A3: Estimate Number
A4: Project Name
A5: GC / Client
A6: NBS Estimator
A7: Primary Market
A8: Owner
A9: Region
A10: Estimate Status
A11: Due Date
A12: Anticipated Start
A13: Anticipated Finish
... A21: ACTIVE SCOPES (Include = Yes to bid / calculate this scope everywhere else in the workbook)
A22: Include? | B22: Scope | C22: CSI Code | D22: Notes
A23: Yes | B23: =Lists!B2 | C23: =Lists!C2
A24: Yes | B24: =Lists!B3 | C24: =Lists!C3
A25: Yes | B25: =Lists!B4 | C25: =Lists!C4
A26: Yes | B26: =Lists!B5 | C26: =Lists!C5
A27: Yes | B27: =Lists!B6 | C27: =Lists!C6
A28: Yes | B28: =Lists!B7 | C28: =Lists!C7
A29: Yes | B29: =Lists!B8 | C29: =Lists!C8
A30: Yes | B30: =Lists!B9 | C30: =Lists!C9
A31: Yes | B31: =Lists!B10 | C31: =Lists!C10
A32: Yes | B32: =Lists!B11 | C32: =Lists!C11
A33: Yes | B33: =Lists!B12 | C33: =Lists!C12
A34: Yes | B34: =Lists!B13 | C34: =Lists!C13
... A42: Yes | B42: =Lists!B21 | C42: =Lists!C21
A44: Scope list and CSI codes are pulled from the hidden Lists sheet (single source of truth). Set Include=No to drop a scope from every calculation without deleting its line items.

Sheet Lines
A1: LINE ITEMS — ALL SCOPES CONSOLIDATED (one flat table; pick a Scope per row, add rows anywhere)
A2: Blue = your input | Black = auto-calculated formula | Grey header = informational, safe to delete | White header = required for calculations — do not delete (Scope, Qty, Unit Material Cost, Freight, Labor/Install, Line Total, Breakout Group)
A3: Scope | B3: CSI Code | C3: Spec No. | D3: Spec Title | E3: Plan Callout | F3: Description | G3: Model No. | H3: Manufacturer | I3: Qty | J3: UOM | K3: Unit Material Cost | L3: Ext Material | M3: Freight (Ext $) | N3: Labor/Install (Ext $) | O3: Line Total | P3: Breakout Group | Q3: Esc Override % (reference only) | R3: Quote Vendor | S3: Source | T3: Has Backup | U3: Notes / Remarks
B4: =IFERROR(INDEX(Lists!$C$2:$C$21,MATCH(A4,Lists!$B$2:$B$21,0)),"") | L4: =I4*K4 | O4: =L4+M4+N4
B5: =IFERROR(INDEX(Lists!$C$2:$C$21,MATCH(A5,Lists!$B$2:$B$21,0)),"") | L5: =I5*K5 | O5: =L5+M5+N5
B6: =IFERROR(INDEX(Lists!$C$2:$C$21,MATCH(A6,Lists!$B$2:$B$21,0)),"") | L6: =I6*K6 | O6: =L6+M6+N6
B7: =IFERROR(INDEX(Lists!$C$2:$C$21,MATCH(A7,Lists!$B$2:$B$21,0)),"") | L7: =I7*K7 | O7: =L7+M7+N7
B8: =IFERROR(INDEX(Lists!$C$2:$C$21,MATCH(A8,Lists!$B$2:$B$21,0)),"") | L8: =I8*K8 | O8: =L8+M8+N8
B9: =IFERROR(INDEX(Lists!$C$2:$C$21,MATCH(A9,Lists!$B$2:$B$21,0)),"") | L9: =I9*K9 | O9: =L9+M9+N9
B10: =IFERROR(INDEX(Lists!$C$2:$C$21,MATCH(A10,Lists!$B$2:$B$21,0)),"") | L10: =I10*K10 | O10: =L10+M10+N10
B11: =IFERROR(INDEX(Lists!$C$2:$C$21,MATCH(A11,Lists!$B$2:$B$21,0)),"") | L11: =I11*K11 | O11: =L11+M11+N11
B12: =IFERROR(INDEX(Lists!$C$2:$C$21,MATCH(A12,Lists!$B$2:$B$21,0)),"") | L12: =I12*K12 | O12: =L12+M12+N12
B13: =IFERROR(INDEX(Lists!$C$2:$C$21,MATCH(A13,Lists!$B$2:$B$21,0)),"") | L13: =I13*K13 | O13: =L13+M13+N13
B14: =IFERROR(INDEX(Lists!$C$2:$C$21,MATCH(A14,Lists!$B$2:$B$21,0)),"") | L14: =I14*K14 | O14: =L14+M14+N14
B15: =IFERROR(INDEX(Lists!$C$2:$C$21,MATCH(A15,Lists!$B$2:$B$21,0)),"") | L15: =I15*K15 | O15: =L15+M15+N15
... B303: =IFERROR(INDEX(Lists!$C$2:$C$21,MATCH(A303,Lists!$B$2:$B$21,0)),"") | L303: =I303*K303 | O303: =L303+M303+N303

Sheet Markups
A1: MARKUPS & BOTTOM-LINE CALCULATIONS
A3: GLOBAL DEFAULT RATES (per-scope rows below default to these; type over a scope's rate to override just that scope)
A4: Tax Rate (applied to Material + Freight) | G4: 0
A5: Contingency Rate | G5: 0
A6: Escalation Rate | G6: 0
A7: Overhead Rate — requires executive approval to change | G7: 0.08
A8: Fee Rate (margin-based, Selling = Cost ÷ (1 − Fee%)) — requires executive approval to change | G8: 0.05
A9: Bond / Insurance Rate | G9: 0
A11: PER-SCOPE BID CHAIN (Material/Freight/Labor auto-pulled from the Lines tab by Scope)
A12: Scope | B12: CSI Code | C12: Active? | D12: Material | E12: Freight | F12: Labor | G12: Tax Rate % | H12: Tax $ | I12: Category Subtotal | J12: Contingency Rate % | K12: Contingency $ | L12: Escalation Rate % | M12: Escalation $ | N12: Overhead Rate % | O12: Overhead $ | P12: Sub Total 1 | Q12: Fee Rate % (margin) | R12: Fee $ | S12: Sub Total 2 | T12: Bond/Ins Rate % | U12: Bond/Ins $ | V12: Grand Total | W12: Adjustment $ | X12: ADJUSTED GRAND TOTAL
A13: ='Project Info'!B23 | B13: ='Project Info'!C23 | C13: ='Project Info'!A23 | D13: =SUMIFS(Lines!$L$4:$L$303,Lines!$A$4:$A$303,A13) | E13: =SUMIFS(Lines!$M$4:$M$303,Lines!$A$4:$A$303,A13) | F13: =SUMIFS(Lines!$N$4:$N$303,Lines!$A$4:$A$303,A13) | G13: =$G$4 | H13: =(D13+E13)*G13 | I13: =D13+E13+F13+H13 | J13: =$G$5 | K13: =I13*J13 | L13: =$G$6 | M13: =D13*L13 | N13: =$G$7 | O13: =I13*N13 | P13: =I13+K13+M13+O13 | Q13: =$G$8 | R13: =IF(Q13>=1,0,P13/(1-Q13)-P13) | S13: =P13+R13 | T13: =$G$9 | U13: =S13*T13 | V13: =ROUND(S13+U13,0) | W13: 0 | X13: =V13+W13
A14: ='Project Info'!B24 | B14: ='Project Info'!C24 | C14: ='Project Info'!A24 | D14: =SUMIFS(Lines!$L$4:$L$303,Lines!$A$4:$A$303,A14) | E14: =SUMIFS(Lines!$M$4:$M$303,Lines!$A$4:$A$303,A14) | F14: =SUMIFS(Lines!$N$4:$N$303,Lines!$A$4:$A$303,A14) | G14: =$G$4 | H14: =(D14+E14)*G14 | I14: =D14+E14+F14+H14 | J14: =$G$5 | K14: =I14*J14 | L14: =$G$6 | M14: =D14*L14 | N14: =$G$7 | O14: =I14*N14 | P14: =I14+K14+M14+O14 | Q14: =$G$8 | R14: =IF(Q14>=1,0,P14/(1-Q14)-P14) | S14: =P14+R14 | T14: =$G$9 | U14: =S14*T14 | V14: =ROUND(S14+U14,0) | W14: 0 | X14: =V14+W14
A15: ='Project Info'!B25 | B15: ='Project Info'!C25 | C15: ='Project Info'!A25 | D15: =SUMIFS(Lines!$L$4:$L$303,Lines!$A$4:$A$303,A15) | E15: =SUMIFS(Lines!$M$4:$M$303,Lines!$A$4:$A$303,A15) | F15: =SUMIFS(Lines!$N$4:$N$303,Lines!$A$4:$A$303,A15) | G15: =$G$4 | H15: =(D15+E15)*G15 | I15: =D15+E15+F15+H15 | J15: =$G$5 | K15: =I15*J15 | L15: =$G$6 | M15: =D15*L15 | N15: =$G$7 | O15: =I15*N15 | P15: =I15+K15+M15+O15 | Q15: =$G$8 | R15: =IF(Q15>=1,0,P15/(1-Q15)-P15) | S15: =P15+R15 | T15: =$G$9 | U15: =S15*T15 | V15: =ROUND(S15+U15,0) | W15: 0 | X15: =V15+W15
A16: ='Project Info'!B26 | B16: ='Project Info'!C26 | C16: ='Project Info'!A26 | D16: =SUMIFS(Lines!$L$4:$L$303,Lines!$A$4:$A$303,A16) | E16: =SUMIFS(Lines!$M$4:$M$303,Lines!$A$4:$A$303,A16) | F16: =SUMIFS(Lines!$N$4:$N$303,Lines!$A$4:$A$303,A16) | G16: =$G$4 | H16: =(D16+E16)*G16 | I16: =D16+E16+F16+H16 | J16: =$G$5 | K16: =I16*J16 | L16: =$G$6 | M16: =D16*L16 | N16: =$G$7 | O16: =I16*N16 | P16: =I16+K16+M16+O16 | Q16: =$G$8 | R16: =IF(Q16>=1,0,P16/(1-Q16)-P16) | S16: =P16+R16 | T16: =$G$9 | U16: =S16*T16 | V16: =ROUND(S16+U16,0) | W16: 0 | X16: =V16+W16
A17: ='Project Info'!B27 | B17: ='Project Info'!C27 | C17: ='Project Info'!A27 | D17: =SUMIFS(Lines!$L$4:$L$303,Lines!$A$4:$A$303,A17) | E17: =SUMIFS(Lines!$M$4:$M$303,Lines!$A$4:$A$303,A17) | F17: =SUMIFS(Lines!$N$4:$N$303,Lines!$A$4:$A$303,A17) | G17: =$G$4 | H17: =(D17+E17)*G17 | I17: =D17+E17+F17+H17 | J17: =$G$5 | K17: =I17*J17 | L17: =$G$6 | M17: =D17*L17 | N17: =$G$7 | O17: =I17*N17 | P17: =I17+K17+M17+O17 | Q17: =$G$8 | R17: =IF(Q17>=1,0,P17/(1-Q17)-P17) | S17: =P17+R17 | T17: =$G$9 | U17: =S17*T17 | V17: =ROUND(S17+U17,0) | W17: 0 | X17: =V17+W17
A18: ='Project Info'!B28 | B18: ='Project Info'!C28 | C18: ='Project Info'!A28 | D18: =SUMIFS(Lines!$L$4:$L$303,Lines!$A$4:$A$303,A18) | E18: =SUMIFS(Lines!$M$4:$M$303,Lines!$A$4:$A$303,A18) | F18: =SUMIFS(Lines!$N$4:$N$303,Lines!$A$4:$A$303,A18) | G18: =$G$4 | H18: =(D18+E18)*G18 | I18: =D18+E18+F18+H18 | J18: =$G$5 | K18: =I18*J18 | L18: =$G$6 | M18: =D18*L18 | N18: =$G$7 | O18: =I18*N18 | P18: =I18+K18+M18+O18 | Q18: =$G$8 | R18: =IF(Q18>=1,0,P18/(1-Q18)-P18) | S18: =P18+R18 | T18: =$G$9 | U18: =S18*T18 | V18: =ROUND(S18+U18,0) | W18: 0 | X18: =V18+W18
A19: ='Project Info'!B29 | B19: ='Project Info'!C29 | C19: ='Project Info'!A29 | D19: =SUMIFS(Lines!$L$4:$L$303,Lines!$A$4:$A$303,A19) | E19: =SUMIFS(Lines!$M$4:$M$303,Lines!$A$4:$A$303,A19) | F19: =SUMIFS(Lines!$N$4:$N$303,Lines!$A$4:$A$303,A19) | G19: =$G$4 | H19: =(D19+E19)*G19 | I19: =D19+E19+F19+H19 | J19: =$G$5 | K19: =I19*J19 | L19: =$G$6 | M19: =D19*L19 | N19: =$G$7 | O19: =I19*N19 | P19: =I19+K19+M19+O19 | Q19: =$G$8 | R19: =IF(Q19>=1,0,P19/(1-Q19)-P19) | S19: =P19+R19 | T19: =$G$9 | U19: =S19*T19 | V19: =ROUND(S19+U19,0) | W19: 0 | X19: =V19+W19
A20: ='Project Info'!B30 | B20: ='Project Info'!C30 | C20: ='Project Info'!A30 | D20: =SUMIFS(Lines!$L$4:$L$303,Lines!$A$4:$A$303,A20) | E20: =SUMIFS(Lines!$M$4:$M$303,Lines!$A$4:$A$303,A20) | F20: =SUMIFS(Lines!$N$4:$N$303,Lines!$A$4:$A$303,A20) | G20: =$G$4 | H20: =(D20+E20)*G20 | I20: =D20+E20+F20+H20 | J20: =$G$5 | K20: =I20*J20 | L20: =$G$6 | M20: =D20*L20 | N20: =$G$7 | O20: =I20*N20 | P20: =I20+K20+M20+O20 | Q20: =$G$8 | R20: =IF(Q20>=1,0,P20/(1-Q20)-P20) | S20: =P20+R20 | T20: =$G$9 | U20: =S20*T20 | V20: =ROUND(S20+U20,0) | W20: 0 | X20: =V20+W20
A21: ='Project Info'!B31 | B21: ='Project Info'!C31 | C21: ='Project Info'!A31 | D21: =SUMIFS(Lines!$L$4:$L$303,Lines!$A$4:$A$303,A21) | E21: =SUMIFS(Lines!$M$4:$M$303,Lines!$A$4:$A$303,A21) | F21: =SUMIFS(Lines!$N$4:$N$303,Lines!$A$4:$A$303,A21) | G21: =$G$4 | H21: =(D21+E21)*G21 | I21: =D21+E21+F21+H21 | J21: =$G$5 | K21: =I21*J21 | L21: =$G$6 | M21: =D21*L21 | N21: =$G$7 | O21: =I21*N21 | P21: =I21+K21+M21+O21 | Q21: =$G$8 | R21: =IF(Q21>=1,0,P21/(1-Q21)-P21) | S21: =P21+R21 | T21: =$G$9 | U21: =S21*T21 | V21: =ROUND(S21+U21,0) | W21: 0 | X21: =V21+W21
A22: ='Project Info'!B32 | B22: ='Project Info'!C32 | C22: ='Project Info'!A32 | D22: =SUMIFS(Lines!$L$4:$L$303,Lines!$A$4:$A$303,A22) | E22: =SUMIFS(Lines!$M$4:$M$303,Lines!$A$4:$A$303,A22) | F22: =SUMIFS(Lines!$N$4:$N$303,Lines!$A$4:$A$303,A22) | G22: =$G$4 | H22: =(D22+E22)*G22 | I22: =D22+E22+F22+H22 | J22: =$G$5 | K22: =I22*J22 | L22: =$G$6 | M22: =D22*L22 | N22: =$G$7 | O22: =I22*N22 | P22: =I22+K22+M22+O22 | Q22: =$G$8 | R22: =IF(Q22>=1,0,P22/(1-Q22)-P22) | S22: =P22+R22 | T22: =$G$9 | U22: =S22*T22 | V22: =ROUND(S22+U22,0) | W22: 0 | X22: =V22+W22
A23: ='Project Info'!B33 | B23: ='Project Info'!C33 | C23: ='Project Info'!A33 | D23: =SUMIFS(Lines!$L$4:$L$303,Lines!$A$4:$A$303,A23) | E23: =SUMIFS(Lines!$M$4:$M$303,Lines!$A$4:$A$303,A23) | F23: =SUMIFS(Lines!$N$4:$N$303,Lines!$A$4:$A$303,A23) | G23: =$G$4 | H23: =(D23+E23)*G23 | I23: =D23+E23+F23+H23 | J23: =$G$5 | K23: =I23*J23 | L23: =$G$6 | M23: =D23*L23 | N23: =$G$7 | O23: =I23*N23 | P23: =I23+K23+M23+O23 | Q23: =$G$8 | R23: =IF(Q23>=1,0,P23/(1-Q23)-P23) | S23: =P23+R23 | T23: =$G$9 | U23: =S23*T23 | V23: =ROUND(S23+U23,0) | W23: 0 | X23: =V23+W23
A24: ='Project Info'!B34 | B24: ='Project Info'!C34 | C24: ='Project Info'!A34 | D24: =SUMIFS(Lines!$L$4:$L$303,Lines!$A$4:$A$303,A24) | E24: =SUMIFS(Lines!$M$4:$M$303,Lines!$A$4:$A$303,A24) | F24: =SUMIFS(Lines!$N$4:$N$303,Lines!$A$4:$A$303,A24) | G24: =$G$4 | H24: =(D24+E24)*G24 | I24: =D24+E24+F24+H24 | J24: =$G$5 | K24: =I24*J24 | L24: =$G$6 | M24: =D24*L24 | N24: =$G$7 | O24: =I24*N24 | P24: =I24+K24+M24+O24 | Q24: =$G$8 | R24: =IF(Q24>=1,0,P24/(1-Q24)-P24) | S24: =P24+R24 | T24: =$G$9 | U24: =S24*T24 | V24: =ROUND(S24+U24,0) | W24: 0 | X24: =V24+W24
... A32: ='Project Info'!B42 | B32: ='Project Info'!C42 | C32: ='Project Info'!A42 | D32: =SUMIFS(Lines!$L$4:$L$303,Lines!$A$4:$A$303,A32) | E32: =SUMIFS(Lines!$M$4:$M$303,Lines!$A$4:$A$303,A32) | F32: =SUMIFS(Lines!$N$4:$N$303,Lines!$A$4:$A$303,A32) | G32: =$G$4 | H32: =(D32+E32)*G32 | I32: =D32+E32+F32+H32 | J32: =$G$5 | K32: =I32*J32 | L32: =$G$6 | M32: =D32*L32 | N32: =$G$7 | O32: =I32*N32 | P32: =I32+K32+M32+O32 | Q32: =$G$8 | R32: =IF(Q32>=1,0,P32/(1-Q32)-P32) | S32: =P32+R32 | T32: =$G$9 | U32: =S32*T32 | V32: =ROUND(S32+U32,0) | W32: 0 | X32: =V32+W32
A33: TOTAL / BOTTOM LINE (active scopes only) | D33: =SUMPRODUCT(($C$13:$C$32="Yes")*(D13:D32)) | E33: =SUMPRODUCT(($C$13:$C$32="Yes")*(E13:E32)) | F33: =SUMPRODUCT(($C$13:$C$32="Yes")*(F13:F32)) | H33: =SUMPRODUCT(($C$13:$C$32="Yes")*(H13:H32)) | I33: =SUMPRODUCT(($C$13:$C$32="Yes")*(I13:I32)) | K33: =SUMPRODUCT(($C$13:$C$32="Yes")*(K13:K32)) | M33: =SUMPRODUCT(($C$13:$C$32="Yes")*(M13:M32)) | O33: =SUMPRODUCT(($C$13:$C$32="Yes")*(O13:O32)) | P33: =SUMPRODUCT(($C$13:$C$32="Yes")*(P13:P32)) | R33: =SUMPRODUCT(($C$13:$C$32="Yes")*(R13:R32)) | S33: =SUMPRODUCT(($C$13:$C$32="Yes")*(S13:S32)) | U33: =SUMPRODUCT(($C$13:$C$32="Yes")*(U13:U32)) | V33: =SUMPRODUCT(($C$13:$C$32="Yes")*(V13:V32)) | W33: =SUMPRODUCT(($C$13:$C$32="Yes")*(W13:W32)) | X33: =SUMPRODUCT(($C$13:$C$32="Yes")*(X13:X32))
A35: ESTIMATE GRAND TOTAL (bottom line, all active scopes) | X35: =X33
A37: Chain order (matches the legacy NBS estimate workbooks): Material+Freight+Labor → Tax(Mat+Freight) → Category Subtotal → +Contingency, +Escalation(on Material), +Overhead → Sub Total 1 → +Fee (margin-based, per AiPM Toolbelt: Fee$ = SubTotal1÷(1−Fee%) − SubTotal1) → Sub Total 2 → +Bond/Insurance → Grand Total (rounded) → + manual Adjustment $ → Adjusted Grand Total.

Sheet Breakout
A1: BREAKOUT — cost buckets by building / phase / area / floor
A3: 1. DEFINE BREAKOUT GROUPS (leave Freight Method = Proportional unless you have a manual freight number for this group)
A4: Code | B4: Label | C4: Type | D4: OH Override % | E4: Fee Override % | F4: Esc Override % | G4: Freight Method | H4: Manual Freight $
G5: Proportional
G6: Proportional
G7: Proportional
G8: Proportional
G9: Proportional
G10: Proportional
G11: Proportional
G12: Proportional
G13: Proportional
G14: Proportional
A16: 2. BREAKOUT ROLLUP (auto-calculated from the Lines tab's Breakout Group column)
A17: Code | B17: Label | C17: Material | D17: Freight | E17: Labor | F17: Tax Rate % | G17: Tax $ | H17: Category Subtotal | I17: Contingency Rate % | J17: Contingency $ | K17: Esc Rate % | L17: Esc $ | M17: OH Rate % | N17: OH $ | O17: Sub Total 1 | P17: Fee Rate % (margin) | Q17: Fee $ | R17: Sub Total 2 | S17: Bond Rate % | T17: Bond $ | U17: GROUP TOTAL
A18: =A5 | B18: =B5 | C18: =SUMIFS(Lines!$L$4:$L$303,Lines!$P$4:$P$303,A18) | D18: =IF(G5="Manual",H5,IF(Markups!$D$33=0,0,C18/Markups!$D$33*Markups!$E$33)) | E18: =SUMIFS(Lines!$N$4:$N$303,Lines!$P$4:$P$303,A18) | F18: =Markups!$G$4 | G18: =(C18+D18)*F18 | H18: =C18+D18+E18+G18 | I18: =Markups!$G$5 | J18: =H18*I18 | K18: =IF(F5<>"",F5,Markups!$G$6) | L18: =C18*K18 | M18: =IF(D5<>"",D5,Markups!$G$7) | N18: =H18*M18 | O18: =H18+J18+L18+N18 | P18: =IF(E5<>"",E5,Markups!$G$8) | Q18: =IF(P18>=1,0,O18/(1-P18)-O18) | R18: =O18+Q18 | S18: =Markups!$G$9 | T18: =R18*S18 | U18: =ROUND(R18+T18,0)
A19: =A6 | B19: =B6 | C19: =SUMIFS(Lines!$L$4:$L$303,Lines!$P$4:$P$303,A19) | D19: =IF(G6="Manual",H6,IF(Markups!$D$33=0,0,C19/Markups!$D$33*Markups!$E$33)) | E19: =SUMIFS(Lines!$N$4:$N$303,Lines!$P$4:$P$303,A19) | F19: =Markups!$G$4 | G19: =(C19+D19)*F19 | H19: =C19+D19+E19+G19 | I19: =Markups!$G$5 | J19: =H19*I19 | K19: =IF(F6<>"",F6,Markups!$G$6) | L19: =C19*K19 | M19: =IF(D6<>"",D6,Markups!$G$7) | N19: =H19*M19 | O19: =H19+J19+L19+N19 | P19: =IF(E6<>"",E6,Markups!$G$8) | Q19: =IF(P19>=1,0,O19/(1-P19)-O19) | R19: =O19+Q19 | S19: =Markups!$G$9 | T19: =R19*S19 | U19: =ROUND(R19+T19,0)
A20: =A7 | B20: =B7 | C20: =SUMIFS(Lines!$L$4:$L$303,Lines!$P$4:$P$303,A20) | D20: =IF(G7="Manual",H7,IF(Markups!$D$33=0,0,C20/Markups!$D$33*Markups!$E$33)) | E20: =SUMIFS(Lines!$N$4:$N$303,Lines!$P$4:$P$303,A20) | F20: =Markups!$G$4 | G20: =(C20+D20)*F20 | H20: =C20+D20+E20+G20 | I20: =Markups!$G$5 | J20: =H20*I20 | K20: =IF(F7<>"",F7,Markups!$G$6) | L20: =C20*K20 | M20: =IF(D7<>"",D7,Markups!$G$7) | N20: =H20*M20 | O20: =H20+J20+L20+N20 | P20: =IF(E7<>"",E7,Markups!$G$8) | Q20: =IF(P20>=1,0,O20/(1-P20)-O20) | R20: =O20+Q20 | S20: =Markups!$G$9 | T20: =R20*S20 | U20: =ROUND(R20+T20,0)
A21: =A8 | B21: =B8 | C21: =SUMIFS(Lines!$L$4:$L$303,Lines!$P$4:$P$303,A21) | D21: =IF(G8="Manual",H8,IF(Markups!$D$33=0,0,C21/Markups!$D$33*Markups!$E$33)) | E21: =SUMIFS(Lines!$N$4:$N$303,Lines!$P$4:$P$303,A21) | F21: =Markups!$G$4 | G21: =(C21+D21)*F21 | H21: =C21+D21+E21+G21 | I21: =Markups!$G$5 | J21: =H21*I21 | K21: =IF(F8<>"",F8,Markups!$G$6) | L21: =C21*K21 | M21: =IF(D8<>"",D8,Markups!$G$7) | N21: =H21*M21 | O21: =H21+J21+L21+N21 | P21: =IF(E8<>"",E8,Markups!$G$8) | Q21: =IF(P21>=1,0,O21/(1-P21)-O21) | R21: =O21+Q21 | S21: =Markups!$G$9 | T21: =R21*S21 | U21: =ROUND(R21+T21,0)
A22: =A9 | B22: =B9 | C22: =SUMIFS(Lines!$L$4:$L$303,Lines!$P$4:$P$303,A22) | D22: =IF(G9="Manual",H9,IF(Markups!$D$33=0,0,C22/Markups!$D$33*Markups!$E$33)) | E22: =SUMIFS(Lines!$N$4:$N$303,Lines!$P$4:$P$303,A22) | F22: =Markups!$G$4 | G22: =(C22+D22)*F22 | H22: =C22+D22+E22+G22 | I22: =Markups!$G$5 | J22: =H22*I22 | K22: =IF(F9<>"",F9,Markups!$G$6) | L22: =C22*K22 | M22: =IF(D9<>"",D9,Markups!$G$7) | N22: =H22*M22 | O22: =H22+J22+L22+N22 | P22: =IF(E9<>"",E9,Markups!$G$8) | Q22: =IF(P22>=1,0,O22/(1-P22)-O22) | R22: =O22+Q22 | S22: =Markups!$G$9 | T22: =R22*S22 | U22: =ROUND(R22+T22,0)
A23: =A10 | B23: =B10 | C23: =SUMIFS(Lines!$L$4:$L$303,Lines!$P$4:$P$303,A23) | D23: =IF(G10="Manual",H10,IF(Markups!$D$33=0,0,C23/Markups!$D$33*Markups!$E$33)) | E23: =SUMIFS(Lines!$N$4:$N$303,Lines!$P$4:$P$303,A23) | F23: =Markups!$G$4 | G23: =(C23+D23)*F23 | H23: =C23+D23+E23+G23 | I23: =Markups!$G$5 | J23: =H23*I23 | K23: =IF(F10<>"",F10,Markups!$G$6) | L23: =C23*K23 | M23: =IF(D10<>"",D10,Markups!$G$7) | N23: =H23*M23 | O23: =H23+J23+L23+N23 | P23: =IF(E10<>"",E10,Markups!$G$8) | Q23: =IF(P23>=1,0,O23/(1-P23)-O23) | R23: =O23+Q23 | S23: =Markups!$G$9 | T23: =R23*S23 | U23: =ROUND(R23+T23,0)
A24: =A11 | B24: =B11 | C24: =SUMIFS(Lines!$L$4:$L$303,Lines!$P$4:$P$303,A24) | D24: =IF(G11="Manual",H11,IF(Markups!$D$33=0,0,C24/Markups!$D$33*Markups!$E$33)) | E24: =SUMIFS(Lines!$N$4:$N$303,Lines!$P$4:$P$303,A24) | F24: =Markups!$G$4 | G24: =(C24+D24)*F24 | H24: =C24+D24+E24+G24 | I24: =Markups!$G$5 | J24: =H24*I24 | K24: =IF(F11<>"",F11,Markups!$G$6) | L24: =C24*K24 | M24: =IF(D11<>"",D11,Markups!$G$7) | N24: =H24*M24 | O24: =H24+J24+L24+N24 | P24: =IF(E11<>"",E11,Markups!$G$8) | Q24: =IF(P24>=1,0,O24/(1-P24)-O24) | R24: =O24+Q24 | S24: =Markups!$G$9 | T24: =R24*S24 | U24: =ROUND(R24+T24,0)
A25: =A12 | B25: =B12 | C25: =SUMIFS(Lines!$L$4:$L$303,Lines!$P$4:$P$303,A25) | D25: =IF(G12="Manual",H12,IF(Markups!$D$33=0,0,C25/Markups!$D$33*Markups!$E$33)) | E25: =SUMIFS(Lines!$N$4:$N$303,Lines!$P$4:$P$303,A25) | F25: =Markups!$G$4 | G25: =(C25+D25)*F25 | H25: =C25+D25+E25+G25 | I25: =Markups!$G$5 | J25: =H25*I25 | K25: =IF(F12<>"",F12,Markups!$G$6) | L25: =C25*K25 | M25: =IF(D12<>"",D12,Markups!$G$7) | N25: =H25*M25 | O25: =H25+J25+L25+N25 | P25: =IF(E12<>"",E12,Markups!$G$8) | Q25: =IF(P25>=1,0,O25/(1-P25)-O25) | R25: =O25+Q25 | S25: =Markups!$G$9 | T25: =R25*S25 | U25: =ROUND(R25+T25,0)
A26: =A13 | B26: =B13 | C26: =SUMIFS(Lines!$L$4:$L$303,Lines!$P$4:$P$303,A26) | D26: =IF(G13="Manual",H13,IF(Markups!$D$33=0,0,C26/Markups!$D$33*Markups!$E$33)) | E26: =SUMIFS(Lines!$N$4:$N$303,Lines!$P$4:$P$303,A26) | F26: =Markups!$G$4 | G26: =(C26+D26)*F26 | H26: =C26+D26+E26+G26 | I26: =Markups!$G$5 | J26: =H26*I26 | K26: =IF(F13<>"",F13,Markups!$G$6) | L26: =C26*K26 | M26: =IF(D13<>"",D13,Markups!$G$7) | N26: =H26*M26 | O26: =H26+J26+L26+N26 | P26: =IF(E13<>"",E13,Markups!$G$8) | Q26: =IF(P26>=1,0,O26/(1-P26)-O26) | R26: =O26+Q26 | S26: =Markups!$G$9 | T26: =R26*S26 | U26: =ROUND(R26+T26,0)
A27: =A14 | B27: =B14 | C27: =SUMIFS(Lines!$L$4:$L$303,Lines!$P$4:$P$303,A27) | D27: =IF(G14="Manual",H14,IF(Markups!$D$33=0,0,C27/Markups!$D$33*Markups!$E$33)) | E27: =SUMIFS(Lines!$N$4:$N$303,Lines!$P$4:$P$303,A27) | F27: =Markups!$G$4 | G27: =(C27+D27)*F27 | H27: =C27+D27+E27+G27 | I27: =Markups!$G$5 | J27: =H27*I27 | K27: =IF(F14<>"",F14,Markups!$G$6) | L27: =C27*K27 | M27: =IF(D14<>"",D14,Markups!$G$7) | N27: =H27*M27 | O27: =H27+J27+L27+N27 | P27: =IF(E14<>"",E14,Markups!$G$8) | Q27: =IF(P27>=1,0,O27/(1-P27)-O27) | R27: =O27+Q27 | S27: =Markups!$G$9 | T27: =R27*S27 | U27: =ROUND(R27+T27,0)
A29: RECONCILIATION | B29: Breakout Sum: | C29: =SUM(U18:U27) | D29: vs. Markups Grand Total: | E29: =Markups!X33 | F29: Difference: | G29: =C29-E29 | H29: =IF(ROUND(G29,2)=0,"OK","Unallocated lines — assign every Lines row to a Breakout Group")
A31: This rollup mirrors the Markups tab's bid chain exactly (same rate cells, same order) so the reconciliation ties to $0 once every active line item is assigned to a Breakout Group. If a group mixes line items from scopes that carry different per-scope OH/Fee/Escalation overrides on the Markups tab, the group uses its own single OH/Fee/Esc Override (or the global default) — so a mixed-scope group's total may not exactly equal the sum of those lines' scope-level totals; use per-group overrides to match if needed.

Sheet Proposal
A1: PROPOSAL / FURNISH ONLY — DIVISION 10 SPECIALTIES
A2: [Your Company Name / Letterhead]
A4: Date
A5: Proposal # | B5: ='Project Info'!B3
A6: Project | B6: ='Project Info'!B4
A7: GC / Client | B7: ='Project Info'!B5
A8: Attn
A9: Prepared By | B9: ='Project Info'!B6
A11: 01 — SCOPE OF MATERIAL
A12: Scope | B12: CSI Code | C12: Price
A13: =Markups!A13 | B13: =Markups!B13 | C13: =IF(Markups!C13="Yes",Markups!X13,"")
A14: =Markups!A14 | B14: =Markups!B14 | C14: =IF(Markups!C14="Yes",Markups!X14,"")
A15: =Markups!A15 | B15: =Markups!B15 | C15: =IF(Markups!C15="Yes",Markups!X15,"")
A16: =Markups!A16 | B16: =Markups!B16 | C16: =IF(Markups!C16="Yes",Markups!X16,"")
A17: =Markups!A17 | B17: =Markups!B17 | C17: =IF(Markups!C17="Yes",Markups!X17,"")
A18: =Markups!A18 | B18: =Markups!B18 | C18: =IF(Markups!C18="Yes",Markups!X18,"")
A19: =Markups!A19 | B19: =Markups!B19 | C19: =IF(Markups!C19="Yes",Markups!X19,"")
A20: =Markups!A20 | B20: =Markups!B20 | C20: =IF(Markups!C20="Yes",Markups!X20,"")
A21: =Markups!A21 | B21: =Markups!B21 | C21: =IF(Markups!C21="Yes",Markups!X21,"")
A22: =Markups!A22 | B22: =Markups!B22 | C22: =IF(Markups!C22="Yes",Markups!X22,"")
A23: =Markups!A23 | B23: =Markups!B23 | C23: =IF(Markups!C23="Yes",Markups!X23,"")
A24: =Markups!A24 | B24: =Markups!B24 | C24: =IF(Markups!C24="Yes",Markups!X24,"")
... A32: =Markups!A32 | B32: =Markups!B32 | C32: =IF(Markups!C32="Yes",Markups!X32,"")
A33: TOTAL BID | C33: =Markups!X33
A34: Full line-item detail is on the Lines tab (filter/sort by Scope).
A36: 02 — QUALIFICATIONS | 03 — INCLUSIONS | 04 — EXCLUSIONS
A37: Scope | B37: Qualifications | C37: Inclusions | D37: Exclusions
A38: =Markups!A13
A39: =Markups!A14
A40: =Markups!A15
A41: =Markups!A16
A42: =Markups!A17
A43: =Markups!A18
A44: =Markups!A19
A45: =Markups!A20
A46: =Markups!A21
A47: =Markups!A22
A48: =Markups!A23
A49: =Markups!A24
... A57: =Markups!A32
...

Sheet Lists
A1: Scope Key | B1: Scope Label | C1: CSI Code | E1: UOM | F1: Source | G1: Yes/No | H1: Estimate Status | I1: Breakout Type | J1: Freight Method
A2: accessories | B2: Toilet Accessories | C2: 10 28 00 | E2: EA | F2: Manual | G2: Yes | H2: Lead | I2: Building | J2: Proportional
A3: partitions | B3: Toilet Compartments | C3: 10 21 00 | E3: LF | F3: Extracted | G3: No | H3: Estimating | I3: Phase | J3: Manual
A4: fire_ext | B4: Fire Extinguisher Cabinets (FEC) | C4: 10 44 00 | E4: SF | F4: Quote | H4: Submitted | I4: Area
A5: corner_guards | B5: Wall Protection | C5: 10 26 00 | E5: LS | F5: Takeoff | H5: Won | I5: Floor
A6: appliances | B6: Appliances | C6: 11 31 00 | E6: PR | H6: Lost
A7: lockers | B7: Lockers | C7: 10 51 00 | E7: SET | H7: No Bid
A8: display_boards | B8: Visual Displays | C8: 10 11 00 | E8: HR
A9: bike_racks | B9: Bike Racks | C9: 10 73 00 | E9: CY
A10: wire_mesh | B10: Wire Mesh Partitions | C10: 10 22 13
A11: cubicle_curtains | B11: Cubicle Curtains | C11: 12 48 00
A12: med_equipment | B12: Medical Equipment | C12: 11 71 00
A13: expansion_joints | B13: Expansion Joints | C13: 07 95 00
A14: storage_units | B14: Shelving | C14: 10 51 13
A15: equipment | B15: Equipment | C15: 11 00 00
A16: entrance_mats | B16: Entrance Mats | C16: 12 48 13
A17: mailboxes | B17: Mailbox | C17: 10 55 00
A18: flagpoles | B18: Flagpole | C18: 10 75 00
A19: knox_box | B19: Knox Box | C19: 08 71 13
A20: site_furnishing | B20: Site Furnishing | C20: 12 93 00
A21: uncategorized | B21: Uncategorized / Other | C21: —
