Workbook
Name new: 'summary sheet'!#REF!
Name new: 'summary sheet'!#REF!
Name new: 'summary sheet'!#REF!
Name new: 'summary sheet'!#REF!
Name new: 'summary sheet'!#REF!
Name new: 'summary sheet'!#REF!
Name new: 'summary sheet'!#REF!
Name new: 'summary sheet'!#REF!
Name new: 'summary sheet'!#REF!
Name new: 'summary sheet'!#REF!
Name SF_GROSS: 'summary sheet'!#REF!
Name SF_GROSS: 'summary sheet'!#REF!
Name SF_GROSS: 'summary sheet'!#REF!
Name SF_GROSS: 'summary sheet'!#REF!
Name SF_GROSS: 'summary sheet'!#REF!
Name SF_GROSS: 'summary sheet'!#REF!
Name SF_GROSS: 'summary sheet'!#REF!
Name SF_GROSS: 'summary sheet'!#REF!
Name SF_GROSS: 'summary sheet'!#REF!
Name SF_GROSS: 'summary sheet'!#REF!

Sheet summary sheet
A1: PROJECT: | D1: Tax Rate: | E1: 0.0975 | G1: SoCal Labor Rates | AA1: Version 2.1
A2: SHIP TO: | D2: Labor Rate | E2: 120 | G2: 2025 | H2: 120 | I2: (SoCal Labor Rate)
A3: WORK CATEGORY: Summary | D3: Escalation | E3: 0.03 | G3: =+G2+1 -> 2026 | H3: =+H2*1.05 -> 126
A4: BID INFO: | D4: Overhead | E4: 0.08 | G4: =+G3+1 -> 2027 | H4: =+H3*1.05 -> 132.3
A5: =NOW() -> 45940.587 | D5: Bond (%) | E5: 0.006 | G5: =+G4+1 -> 2028 | H5: =+H4*1.05 -> 138.915
D6: Insurance (%) | E6: 0.0125 | G6: =+G5+1 -> 2029 | H6: =+H5*1.05 -> 145.86075
A7: DESCRIPTION | B7: TOTAL
A9: All CATEGORY SUBTOTAL | B9: =SUM('Toilet Accessories'!R61+'Toilet Compartments'!R61+'Wall Protection'!R61+'Bike Racks'!R61+'Wire Mesh Partitions'!R61+Lockers!R61+'Visual Displays'!R61+FEC!R61+'Med Equipment'!R61+Appliances!R61+'Cubicle Curtains'!R61+'Est (9)'!R61+'Est (10)'!R61) -> 0 | G9: Project Start Date | H9: Project End Date
A10: Lifts & Rentals | B10: =SUM('Toilet Accessories'!R64+'Toilet Compartments'!R64+'Wall Protection'!R64+'Bike Racks'!R64+Lockers!R64+'Visual Displays'!R64+FEC!R64+'Wire Mesh Partitions'!R64+'Med Equipment'!R64+Appliances!R64+'Cubicle Curtains'!R64+'Est (9)'!R64+'Est (10)'!R64) -> 0
A11: Superintendent | B11: =SUM('Toilet Accessories'!R65+'Toilet Compartments'!R65+'Wall Protection'!R65+'Bike Racks'!R65+Lockers!R65+'Visual Displays'!R65+FEC!R65+'Wire Mesh Partitions'!R65+'Med Equipment'!R65+Appliances!R65+'Cubicle Curtains'!R65+'Est (9)'!R65+'Est (10)'!R65) -> 0 | I11: ROUND UP TOTALS TOOL
A12: Misc. Hardware & Tools | B12: =SUM('Toilet Accessories'!R66+'Toilet Compartments'!R66+'Wall Protection'!R66+'Bike Racks'!R66+Lockers!R66+'Visual Displays'!R66+FEC!R66+'Wire Mesh Partitions'!R66+'Med Equipment'!R66+Appliances!R66+'Cubicle Curtains'!R66+'Est (9)'!R66+'Est (10)'!R66) -> 0 | I12: =ROUNDUP('Toilet Accessories'!R79,0) -> 0 | J12: ='Toilet Accessories'!A3 -> SCOPE: Toilet Accessories
A13: Field Verification | B13: =SUM('Toilet Accessories'!R67+'Toilet Compartments'!R67+'Wall Protection'!R67+'Bike Racks'!R67+Lockers!R67+'Visual Displays'!R67+FEC!R67+'Wire Mesh Partitions'!R67+'Med Equipment'!R67+Appliances!R67+'Cubicle Curtains'!R67+'Est (9)'!R67+'Est (10)'!R67) -> 0 | I13: =ROUNDUP('Toilet Compartments'!R79,0) -> 0 | J13: ='Toilet Compartments'!A3 -> SCOPE: Toilet Compartments
A14: Receiving & Cleanup | B14: =SUM('Toilet Accessories'!R68+'Toilet Compartments'!R68+'Wall Protection'!R68+'Bike Racks'!R68+Lockers!R68+'Visual Displays'!R68+FEC!R68+'Wire Mesh Partitions'!R68+'Med Equipment'!R68+Appliances!R68+'Cubicle Curtains'!R68+'Est (9)'!R68+'Est (10)'!R68) -> 0 | I14: =ROUNDUP('Wall Protection'!R79,0) -> 0 | J14: ='Wall Protection'!A3 -> SCOPE: Wall Protection
A15: Parking | B15: =SUM('Toilet Accessories'!R69+'Toilet Compartments'!R69+'Wall Protection'!R69+'Bike Racks'!R69+Lockers!R69+'Visual Displays'!R69+FEC!R69+'Wire Mesh Partitions'!R69+'Med Equipment'!R69+Appliances!R69+'Cubicle Curtains'!R69+'Est (9)'!R69+'Est (10)'!R69) -> 0 | I15: =ROUNDUP(Appliances!R79,0) -> 0 | J15: =Appliances!A3 -> SCOPE: Appliances
A16: SUB TOTAL | B16: =SUM('Toilet Accessories'!R70+'Toilet Compartments'!R70+'Wall Protection'!R70+'Bike Racks'!R70+'Wire Mesh Partitions'!R70+Lockers!R70+'Visual Displays'!R70+FEC!R70+'Med Equipment'!R70+Appliances!R70+'Cubicle Curtains'!R70+'Est (9)'!R70+'Est (10)'!R70) -> 0 | C16: =SUM(B9:B15)-B16 -> 0 | D16: check must equal zero | I16: =ROUNDUP(Lockers!R79,0) -> 0 | J16: =Lockers!A3 -> SCOPE: Lockers
A17: ESCALATION (%): | B17: =SUM('Toilet Accessories'!R71+'Toilet Compartments'!R71+'Wall Protection'!R71+'Bike Racks'!R71+'Wire Mesh Partitions'!R71+Lockers!R71+'Visual Displays'!R71+FEC!R71+'Med Equipment'!R71+Appliances!R71+'Cubicle Curtains'!R71+'Est (9)'!R71+'Est (10)'!R71) -> 0 | C17: =B17/B16 -> #DIV/0! | I17: =ROUNDUP('Visual Displays'!R79,0) -> 0 | J17: ='Visual Displays'!A3 -> SCOPE: Visual Displays
A18: OVERHEAD (%): | B18: =SUM('Toilet Accessories'!R72+'Toilet Compartments'!R72+'Wall Protection'!R72+'Bike Racks'!R72+'Wire Mesh Partitions'!R72+Lockers!R72+'Visual Displays'!R72+FEC!R72+'Med Equipment'!R72+Appliances!R72+'Cubicle Curtains'!R72+'Est (9)'!R72+'Est (10)'!R72) -> 0 | C18: =B18/B16 -> #DIV/0! | I18: =ROUNDUP(FEC!R79,0) -> 0 | J18: =FEC!A3 -> SCOPE: FEC
A19: SUB TOTAL | B19: =SUM('Toilet Accessories'!R73+'Toilet Compartments'!R73+'Wall Protection'!R73+'Bike Racks'!R73+'Wire Mesh Partitions'!R73+Lockers!R73+'Visual Displays'!R73+FEC!R73+'Med Equipment'!R73+Appliances!R73+'Cubicle Curtains'!R73+'Est (9)'!R73+'Est (10)'!R73) -> 0 | C19: =SUM(B16:B18)-B19 -> 0 | D19: check must equal zero | I19: =ROUNDUP('Bike Racks'!R79,0) -> 0 | J19: ='Bike Racks'!A3 -> SCOPE: Bike Racks
A20: FEE (%): | B20: =SUM('Toilet Accessories'!R74+'Toilet Compartments'!R74+'Wall Protection'!R74+'Bike Racks'!R74+'Wire Mesh Partitions'!R74+Lockers!R74+'Visual Displays'!R74+FEC!R74+'Med Equipment'!R74+Appliances!R74+'Cubicle Curtains'!R74+'Est (9)'!R74+'Est (10)'!R74) -> 0 | C20: =B20/B19 -> #DIV/0! | I20: =ROUNDUP('Wire Mesh Partitions'!R79,0) -> 0 | J20: ='Wire Mesh Partitions'!A3 -> SCOPE: Wire Mesh Partitions
A21: SUB TOTAL | B21: =SUM('Toilet Accessories'!R75+'Toilet Compartments'!R75+'Wall Protection'!R75+'Bike Racks'!R75+'Wire Mesh Partitions'!R75+Lockers!R75+'Visual Displays'!R75+FEC!R75+'Med Equipment'!R75+Appliances!R75+'Cubicle Curtains'!R75+'Est (9)'!R75+'Est (10)'!R75) -> 0 | C21: =SUM(B19:B20,B22,B24)-B25 -> 0 | D21: check must equal zero | I21: =ROUNDUP('Cubicle Curtains'!R79,0) -> 0 | J21: ='Cubicle Curtains'!A3 -> SCOPE: Cubicle Curtains
A22: BOND (%): | B22: =SUM('Toilet Accessories'!R76+'Toilet Compartments'!R76+'Wall Protection'!R76+'Bike Racks'!R76+'Wire Mesh Partitions'!R76+Lockers!R76+'Visual Displays'!R76+FEC!R76+'Med Equipment'!R76+Appliances!R76+'Cubicle Curtains'!R76+'Est (9)'!R76+'Est (10)'!R76) -> 0 | C22: =SUM(B20:B20)/B19 -> #DIV/0! | D22: Total fee on job | I22: =ROUNDUP('Med Equipment'!R79,0) -> 0 | J22: ='Med Equipment'!A3 -> SCOPE: Med Equipment
A23: SUB TOTAL | B23: =SUM('Toilet Accessories'!R77+'Toilet Compartments'!R77+'Wall Protection'!R77+'Bike Racks'!R77+'Wire Mesh Partitions'!R77+Lockers!R77+'Visual Displays'!R77+FEC!R77+'Med Equipment'!R77+Appliances!R77+'Cubicle Curtains'!R77+'Est (9)'!R77+'Est (10)'!R77) -> 0 | I23: =ROUNDUP('Est (9)'!R79,0) -> 0 | J23: ='Est (9)'!A3 -> SCOPE: Est (9)
A24: INSURANCE (1.25%): | B24: =SUM('Toilet Accessories'!R78+'Toilet Compartments'!R78+'Wall Protection'!R78+'Bike Racks'!R78+'Wire Mesh Partitions'!R78+Lockers!R78+'Visual Displays'!R78+FEC!R78+'Med Equipment'!R78+Appliances!R78+'Cubicle Curtains'!R78+'Est (9)'!R78+'Est (10)'!R78) -> 0 | C24: =SUM(B18+B20)/B16 -> #DIV/0! | I24: =ROUNDUP('Est (10)'!R79,0) -> 0 | J24: ='Est (10)'!A3 -> SCOPE: Est (10)
A25: GRAND TOTAL | B25: =SUM('Toilet Accessories'!R79+'Toilet Compartments'!R79+'Wall Protection'!R79+'Bike Racks'!R79+'Wire Mesh Partitions'!R79+Lockers!R79+'Visual Displays'!R79+FEC!R79+'Med Equipment'!R79+Appliances!R79+'Cubicle Curtains'!R79+'Est (9)'!R79+'Est (10)'!R79) -> 0 | I25: =SUM(I12:I24) -> 0 | J25: PROPOSAL TOTAL
B43: Scope Budget Breakdown
B44: SB | C44: NBS
A45: Labor | B45: =+'Toilet Accessories'!E102+'Toilet Compartments'!E102+'Wall Protection'!E102+Appliances!E102+Lockers!E102+'Visual Displays'!E102+FEC!E102+'Bike Racks'!E102+'Wire Mesh Partitions'!E102+'Cubicle Curtains'!E102+'Med Equipment'!E102+'Est (9)'!E102+'Est (10)'!E102 -> 0
A46: Superintendent | B46: =+'Toilet Accessories'!E103+'Toilet Compartments'!E103+'Wall Protection'!E103+Appliances!E103+Lockers!E103+'Visual Displays'!E103+FEC!E103+'Bike Racks'!E103+'Wire Mesh Partitions'!E103+'Cubicle Curtains'!E103+'Med Equipment'!E103+'Est (9)'!E103+'Est (10)'!E103 -> 0
A47: Installation Material | B47: =+'Toilet Accessories'!E104+'Toilet Compartments'!E104+'Wall Protection'!E104+Appliances!E104+Lockers!E104+'Visual Displays'!E104+FEC!E104+'Bike Racks'!E104+'Wire Mesh Partitions'!E104+'Cubicle Curtains'!E104+'Med Equipment'!E104+'Est (9)'!E104+'Est (10)'!E104 -> 0 | C47: =+'Toilet Accessories'!F104+'Toilet Compartments'!F104+'Wall Protection'!F104+Appliances!F104+Lockers!F104+'Visual Displays'!F104+FEC!F104+'Bike Racks'!F104+'Wire Mesh Partitions'!F104+'Cubicle Curtains'!F104+'Med Equipment'!F104+'Est (9)'!F104+'Est (10)'!F104 -> 0
A48: Rental | B48: =+'Toilet Accessories'!E105+'Toilet Compartments'!E105+'Wall Protection'!E105+Appliances!E105+Lockers!E105+'Visual Displays'!E105+FEC!E105+'Bike Racks'!E105+'Wire Mesh Partitions'!E105+'Cubicle Curtains'!E105+'Med Equipment'!E105+'Est (9)'!E105+'Est (10)'!E105 -> 0 | C48: =+'Toilet Accessories'!F105+'Toilet Compartments'!F105+'Wall Protection'!F105+Appliances!F105+Lockers!F105+'Visual Displays'!F105+FEC!F105+'Bike Racks'!F105+'Wire Mesh Partitions'!F105+'Cubicle Curtains'!F105+'Med Equipment'!F105+'Est (9)'!F105+'Est (10)'!F105 -> 0
A49: OH | B49: =+'Toilet Accessories'!E106+'Toilet Compartments'!E106+'Wall Protection'!E106+Appliances!E106+Lockers!E106+'Visual Displays'!E106+FEC!E106+'Bike Racks'!E106+'Wire Mesh Partitions'!E106+'Cubicle Curtains'!E106+'Med Equipment'!E106+'Est (9)'!E106+'Est (10)'!E106 -> 0 | C49: =+'Toilet Accessories'!F106+'Toilet Compartments'!F106+'Wall Protection'!F106+Appliances!F106+Lockers!F106+'Visual Displays'!F106+FEC!F106+'Bike Racks'!F106+'Wire Mesh Partitions'!F106+'Cubicle Curtains'!F106+'Med Equipment'!F106+'Est (9)'!F106+'Est (10)'!F106 -> 0
A50: Fee | B50: =+'Toilet Accessories'!E107+'Toilet Compartments'!E107+'Wall Protection'!E107+Appliances!E107+Lockers!E107+'Visual Displays'!E107+FEC!E107+'Bike Racks'!E107+'Wire Mesh Partitions'!E107+'Cubicle Curtains'!E107+'Med Equipment'!E107+'Est (9)'!E107+'Est (10)'!E107 -> 0 | C50: =+'Toilet Accessories'!F107+'Toilet Compartments'!F107+'Wall Protection'!F107+Appliances!F107+Lockers!F107+'Visual Displays'!F107+FEC!F107+'Bike Racks'!F107+'Wire Mesh Partitions'!F107+'Cubicle Curtains'!F107+'Med Equipment'!F107+'Est (9)'!F107+'Est (10)'!F107 -> 0
A51: SB SP Total | B51: =SUM(B45:B50) -> 0 | C51: =SUM(C45:C50) -> 0
A52: NBS Scope PA Amount | B52: =C51 -> 0
A53: Scope Total | B53: =B51+C51 -> 0 | C53: =B53-B25+B55+B56 -> 0 | D53: Check
A55: Total Bond | B55: =+'Toilet Accessories'!R76+'Toilet Compartments'!R76+'Wall Protection'!R76+Appliances!R76+Lockers!R76+'Visual Displays'!R76+FEC!R76+'Bike Racks'!R76+'Wire Mesh Partitions'!R76+'Cubicle Curtains'!R76+'Med Equipment'!R76+'Est (9)'!R76+'Est (10)'!R76 -> 0
A56: Total Insurance | B56: =+'Toilet Accessories'!R78+'Toilet Compartments'!R78+'Wall Protection'!R78+Appliances!R78+Lockers!R78+'Visual Displays'!R78+FEC!R78+'Bike Racks'!R78+'Wire Mesh Partitions'!R78+'Cubicle Curtains'!R78+'Med Equipment'!R78+'Est (9)'!R78+'Est (10)'!R78 -> 0

Sheet Toilet Accessories
A1: ='summary sheet'!A1 -> PROJECT:
A2: ='summary sheet'!A2:A2 -> SHIP TO:
A3: {=CONCATENATE("SCOPE: ",MID(CELL("filename",A1),FIND("]",CELL("filename",A1))+1,255))} -> SCOPE: Toilet Accessories
A4: ='summary sheet'!A4 -> BID INFO:
A5: ='summary sheet'!A5 -> 45940.587
J6: * * * * * * * * * * * UNIT COST * * * * * * * * * * * * * * * | N6: * * * * * * * * * * * * * * TOTAL COST * * * * * * * * * * * * * * * * * * | U6: Remarks | X6: BOBRICK
B7: SPEC No. | C7: SPEC TITLE | D7: PLAN CALLOUT | E7: DESCRIPTION | F7: MODEL NUMBER | G7: ITEM QUANTITY | H7: LABOR FACTOR | I7: LABOR RATE | J7: LABOR | K7: MATERIAL | L7: FREIGHT | M7: SUB | N7: LABOR | O7: MATERIAL | P7: FREIGHT | Q7: SUB | R7: TOTAL | S7: BREAKOUT COST | T7: BREAKOUT UNIT PRICE | V7: COPY COST ROW | W7: COPY DESCRIPTION ROW | X7: MATERIAL COST | Y7: LABOR FACTOR | Z7: DESCRIPTION
M8: CONTRACT | Q8: CONTRACT
A9: 1 | I9: ='summary sheet'!$E$2 -> 120 | J9: =SUM(I9*H9)*G9 -> 0 | K9: 0 | L9: 0 | M9: 0 | N9: =J9 -> 0 | O9: =SUM(G9)*K9 -> 0 | P9: =SUM(L9) -> 0 | Q9: =M9 -> 0 | R9: =SUM(N9:Q9) -> 0 | S9: =(R9/($R$61-$R$60))*SUM($R$64:$R$69,$R$71:$R$72,$R$74,$R$76,$R$78,$R$60)+R9 -> #DIV/0! | T9: =S9/G9 -> #DIV/0! | V9: =IF($K9=0,$X9,$K9) | W9: =IF($E9="",$Z9,$E9) | X9: =IF($F9="","",INDEX('Bobrick Material Pricing 2025'!$A$2:$C$1000,MATCH($F9,'Bobrick Material Pricing 2025'!$A$2:$A$1000,0),3)) | Y9: =IF($F9="","",INDEX('Bobrick Labor Factors'!$A$2:$E$556,MATCH($F9,'Bobrick Labor Factors'!$A$2:$A$556,0),5)) | Z9: =IF($F9="","",INDEX('Bobrick Material Pricing 2025'!$A$2:$C$1000,MATCH($F9,'Bobrick Material Pricing 2025'!$A$2:$A$1000,0),2))
A10: 2 | I10: ='summary sheet'!$E$2 -> 120 | J10: =SUM(I10*H10)*G10 -> 0 | K10: 0 | L10: 0 | M10: 0 | N10: =J10 -> 0 | O10: =SUM(G10)*K10 -> 0 | P10: =SUM(L10) -> 0 | Q10: =M10 -> 0 | R10: =SUM(N10:Q10) -> 0 | S10: =(R10/($R$61-$R$60))*SUM($R$64:$R$69,$R$71:$R$72,$R$74,$R$76,$R$78,$R$60)+R10 -> #DIV/0! | T10: =S10/G10 -> #DIV/0! | V10: =IF($K10=0,$X10,$K10) | W10: =IF($E10="",$Z10,$E10) | X10: =IF($F10="","",INDEX('Bobrick Material Pricing 2025'!$A$2:$C$1000,MATCH($F10,'Bobrick Material Pricing 2025'!$A$2:$A$1000,0),3)) | Y10: =IF($F10="","",INDEX('Bobrick Labor Factors'!$A$2:$E$556,MATCH($F10,'Bobrick Labor Factors'!$A$2:$A$556,0),5)) | Z10: =IF($F10="","",INDEX('Bobrick Material Pricing 2025'!$A$2:$C$1000,MATCH($F10,'Bobrick Material Pricing 2025'!$A$2:$A$1000,0),2))
A11: 3 | I11: ='summary sheet'!$E$2 -> 120 | J11: =SUM(I11*H11)*G11 -> 0 | K11: 0 | L11: 0 | M11: 0 | N11: =J11 -> 0 | O11: =SUM(G11)*K11 -> 0 | P11: =SUM(L11) -> 0 | Q11: =M11 -> 0 | R11: =SUM(N11:Q11) -> 0 | S11: =(R11/($R$61-$R$60))*SUM($R$64:$R$69,$R$71:$R$72,$R$74,$R$76,$R$78,$R$60)+R11 -> #DIV/0! | T11: =S11/G11 -> #DIV/0! | V11: =IF($K11=0,$X11,$K11) | W11: =IF($E11="",$Z11,$E11) | X11: =IF($F11="","",INDEX('Bobrick Material Pricing 2025'!$A$2:$C$1000,MATCH($F11,'Bobrick Material Pricing 2025'!$A$2:$A$1000,0),3)) | Y11: =IF($F11="","",INDEX('Bobrick Labor Factors'!$A$2:$E$556,MATCH($F11,'Bobrick Labor Factors'!$A$2:$A$556,0),5)) | Z11: =IF($F11="","",INDEX('Bobrick Material Pricing 2025'!$A$2:$C$1000,MATCH($F11,'Bobrick Material Pricing 2025'!$A$2:$A$1000,0),2))
A12: 4 | I12: ='summary sheet'!$E$2 -> 120 | J12: =SUM(I12*H12)*G12 -> 0 | K12: 0 | L12: 0 | M12: 0 | N12: =J12 -> 0 | O12: =SUM(G12)*K12 -> 0 | P12: =SUM(L12) -> 0 | Q12: =M12 -> 0 | R12: =SUM(N12:Q12) -> 0 | S12: =(R12/($R$61-$R$60))*SUM($R$64:$R$69,$R$71:$R$72,$R$74,$R$76,$R$78,$R$60)+R12 -> #DIV/0! | T12: =S12/G12 -> #DIV/0! | V12: =IF($K12=0,$X12,$K12) | W12: =IF($E12="",$Z12,$E12) | X12: =IF($F12="","",INDEX('Bobrick Material Pricing 2025'!$A$2:$C$1000,MATCH($F12,'Bobrick Material Pricing 2025'!$A$2:$A$1000,0),3)) | Y12: =IF($F12="","",INDEX('Bobrick Labor Factors'!$A$2:$E$556,MATCH($F12,'Bobrick Labor Factors'!$A$2:$A$556,0),5)) | Z12: =IF($F12="","",INDEX('Bobrick Material Pricing 2025'!$A$2:$C$1000,MATCH($F12,'Bobrick Material Pricing 2025'!$A$2:$A$1000,0),2))
A13: 5 | I13: ='summary sheet'!$E$2 -> 120 | J13: =SUM(I13*H13)*G13 -> 0 | K13: 0 | L13: 0 | M13: 0 | N13: =J13 -> 0 | O13: =SUM(G13)*K13 -> 0 | P13: =SUM(L13) -> 0 | Q13: =M13 -> 0 | R13: =SUM(N13:Q13) -> 0 | S13: =(R13/($R$61-$R$60))*SUM($R$64:$R$69,$R$71:$R$72,$R$74,$R$76,$R$78,$R$60)+R13 -> #DIV/0! | T13: =S13/G13 -> #DIV/0! | V13: =IF($K13=0,$X13,$K13) | W13: =IF($E13="",$Z13,$E13) | X13: =IF($F13="","",INDEX('Bobrick Material Pricing 2025'!$A$2:$C$1000,MATCH($F13,'Bobrick Material Pricing 2025'!$A$2:$A$1000,0),3)) | Y13: =IF($F13="","",INDEX('Bobrick Labor Factors'!$A$2:$E$556,MATCH($F13,'Bobrick Labor Factors'!$A$2:$A$556,0),5)) | Z13: =IF($F13="","",INDEX('Bobrick Material Pricing 2025'!$A$2:$C$1000,MATCH($F13,'Bobrick Material Pricing 2025'!$A$2:$A$1000,0),2))
A14: 6 | I14: ='summary sheet'!$E$2 -> 120 | J14: =SUM(I14*H14)*G14 -> 0 | K14: 0 | L14: 0 | M14: 0 | N14: =J14 -> 0 | O14: =SUM(G14)*K14 -> 0 | P14: =SUM(L14) -> 0 | Q14: =M14 -> 0 | R14: =SUM(N14:Q14) -> 0 | S14: =(R14/($R$61-$R$60))*SUM($R$64:$R$69,$R$71:$R$72,$R$74,$R$76,$R$78,$R$60)+R14 -> #DIV/0! | T14: =S14/G14 -> #DIV/0! | V14: =IF($K14=0,$X14,$K14) | W14: =IF($E14="",$Z14,$E14) | X14: =IF($F14="","",INDEX('Bobrick Material Pricing 2025'!$A$2:$C$1000,MATCH($F14,'Bobrick Material Pricing 2025'!$A$2:$A$1000,0),3)) | Y14: =IF($F14="","",INDEX('Bobrick Labor Factors'!$A$2:$E$556,MATCH($F14,'Bobrick Labor Factors'!$A$2:$A$556,0),5)) | Z14: =IF($F14="","",INDEX('Bobrick Material Pricing 2025'!$A$2:$C$1000,MATCH($F14,'Bobrick Material Pricing 2025'!$A$2:$A$1000,0),2))
A15: 7 | I15: ='summary sheet'!$E$2 -> 120 | J15: =SUM(I15*H15)*G15 -> 0 | K15: 0 | L15: 0 | M15: 0 | N15: =J15 -> 0 | O15: =SUM(G15)*K15 -> 0 | P15: =SUM(L15) -> 0 | Q15: =M15 -> 0 | R15: =SUM(N15:Q15) -> 0 | S15: =(R15/($R$61-$R$60))*SUM($R$64:$R$69,$R$71:$R$72,$R$74,$R$76,$R$78,$R$60)+R15 -> #DIV/0! | T15: =S15/G15 -> #DIV/0! | V15: =IF($K15=0,$X15,$K15) | W15: =IF($E15="",$Z15,$E15) | X15: =IF($F15="","",INDEX('Bobrick Material Pricing 2025'!$A$2:$C$1000,MATCH($F15,'Bobrick Material Pricing 2025'!$A$2:$A$1000,0),3)) | Y15: =IF($F15="","",INDEX('Bobrick Labor Factors'!$A$2:$E$556,MATCH($F15,'Bobrick Labor Factors'!$A$2:$A$556,0),5)) | Z15: =IF($F15="","",INDEX('Bobrick Material Pricing 2025'!$A$2:$C$1000,MATCH($F15,'Bobrick Material Pricing 2025'!$A$2:$A$1000,0),2))
A16: 8 | I16: ='summary sheet'!$E$2 -> 120 | J16: =SUM(I16*H16)*G16 -> 0 | K16: 0 | L16: 0 | M16: 0 | N16: =J16 -> 0 | O16: =SUM(G16)*K16 -> 0 | P16: =SUM(L16) -> 0 | Q16: =M16 -> 0 | R16: =SUM(N16:Q16) -> 0 | S16: =(R16/($R$61-$R$60))*SUM($R$64:$R$69,$R$71:$R$72,$R$74,$R$76,$R$78,$R$60)+R16 -> #DIV/0! | T16: =S16/G16 -> #DIV/0! | V16: =IF($K16=0,$X16,$K16) | W16: =IF($E16="",$Z16,$E16) | X16: =IF($F16="","",INDEX('Bobrick Material Pricing 2025'!$A$2:$C$1000,MATCH($F16,'Bobrick Material Pricing 2025'!$A$2:$A$1000,0),3)) | Y16: =IF($F16="","",INDEX('Bobrick Labor Factors'!$A$2:$E$556,MATCH($F16,'Bobrick Labor Factors'!$A$2:$A$556,0),5)) | Z16: =IF($F16="","",INDEX('Bobrick Material Pricing 2025'!$A$2:$C$1000,MATCH($F16,'Bobrick Material Pricing 2025'!$A$2:$A$1000,0),2))
A17: 9 | I17: ='summary sheet'!$E$2 -> 120 | J17: =SUM(I17*H17)*G17 -> 0 | K17: 0 | L17: 0 | M17: 0 | N17: =J17 -> 0 | O17: =SUM(G17)*K17 -> 0 | P17: =SUM(L17) -> 0 | Q17: =M17 -> 0 | R17: =SUM(N17:Q17) -> 0 | S17: =(R17/($R$61-$R$60))*SUM($R$64:$R$69,$R$71:$R$72,$R$74,$R$76,$R$78,$R$60)+R17 -> #DIV/0! | T17: =S17/G17 -> #DIV/0! | V17: =IF($K17=0,$X17,$K17) | W17: =IF($E17="",$Z17,$E17) | X17: =IF($F17="","",INDEX('Bobrick Material Pricing 2025'!$A$2:$C$1000,MATCH($F17,'Bobrick Material Pricing 2025'!$A$2:$A$1000,0),3)) | Y17: =IF($F17="","",INDEX('Bobrick Labor Factors'!$A$2:$E$556,MATCH($F17,'Bobrick Labor Factors'!$A$2:$A$556,0),5)) | Z17: =IF($F17="","",INDEX('Bobrick Material Pricing 2025'!$A$2:$C$1000,MATCH($F17,'Bobrick Material Pricing 2025'!$A$2:$A$1000,0),2))
A18: 10 | I18: ='summary sheet'!$E$2 -> 120 | J18: =SUM(I18*H18)*G18 -> 0 | K18: 0 | L18: 0 | M18: 0 | N18: =J18 -> 0 | O18: =SUM(G18)*K18 -> 0 | P18: =SUM(L18) -> 0 | Q18: =M18 -> 0 | R18: =SUM(N18:Q18) -> 0 | S18: =(R18/($R$61-$R$60))*SUM($R$64:$R$69,$R$71:$R$72,$R$74,$R$76,$R$78,$R$60)+R18 -> #DIV/0! | T18: =S18/G18 -> #DIV/0! | V18: =IF($K18=0,$X18,$K18) | W18: =IF($E18="",$Z18,$E18) | X18: =IF($F18="","",INDEX('Bobrick Material Pricing 2025'!$A$2:$C$1000,MATCH($F18,'Bobrick Material Pricing 2025'!$A$2:$A$1000,0),3)) | Y18: =IF($F18="","",INDEX('Bobrick Labor Factors'!$A$2:$E$556,MATCH($F18,'Bobrick Labor Factors'!$A$2:$A$556,0),5)) | Z18: =IF($F18="","",INDEX('Bobrick Material Pricing 2025'!$A$2:$C$1000,MATCH($F18,'Bobrick Material Pricing 2025'!$A$2:$A$1000,0),2))
A19: 11 | I19: ='summary sheet'!$E$2 -> 120 | J19: =SUM(I19*H19)*G19 -> 0 | K19: 0 | L19: 0 | M19: 0 | N19: =J19 -> 0 | O19: =SUM(G19)*K19 -> 0 | P19: =SUM(L19) -> 0 | Q19: =M19 -> 0 | R19: =SUM(N19:Q19) -> 0 | S19: =(R19/($R$61-$R$60))*SUM($R$64:$R$69,$R$71:$R$72,$R$74,$R$76,$R$78,$R$60)+R19 -> #DIV/0! | T19: =S19/G19 -> #DIV/0! | V19: =IF($K19=0,$X19,$K19) | W19: =IF($E19="",$Z19,$E19) | X19: =IF($F19="","",INDEX('Bobrick Material Pricing 2025'!$A$2:$C$1000,MATCH($F19,'Bobrick Material Pricing 2025'!$A$2:$A$1000,0),3)) | Y19: =IF($F19="","",INDEX('Bobrick Labor Factors'!$A$2:$E$556,MATCH($F19,'Bobrick Labor Factors'!$A$2:$A$556,0),5)) | Z19: =IF($F19="","",INDEX('Bobrick Material Pricing 2025'!$A$2:$C$1000,MATCH($F19,'Bobrick Material Pricing 2025'!$A$2:$A$1000,0),2))
A20: 12 | I20: ='summary sheet'!$E$2 -> 120 | J20: =SUM(I20*H20)*G20 -> 0 | K20: 0 | L20: 0 | M20: 0 | N20: =J20 -> 0 | O20: =SUM(G20)*K20 -> 0 | P20: =SUM(L20) -> 0 | Q20: =M20 -> 0 | R20: =SUM(N20:Q20) -> 0 | S20: =(R20/($R$61-$R$60))*SUM($R$64:$R$69,$R$71:$R$72,$R$74,$R$76,$R$78,$R$60)+R20 -> #DIV/0! | T20: =S20/G20 -> #DIV/0! | V20: =IF($K20=0,$X20,$K20) | W20: =IF($E20="",$Z20,$E20) | X20: =IF($F20="","",INDEX('Bobrick Material Pricing 2025'!$A$2:$C$1000,MATCH($F20,'Bobrick Material Pricing 2025'!$A$2:$A$1000,0),3)) | Y20: =IF($F20="","",INDEX('Bobrick Labor Factors'!$A$2:$E$556,MATCH($F20,'Bobrick Labor Factors'!$A$2:$A$556,0),5)) | Z20: =IF($F20="","",INDEX('Bobrick Material Pricing 2025'!$A$2:$C$1000,MATCH($F20,'Bobrick Material Pricing 2025'!$A$2:$A$1000,0),2))
... A58: 50 | I58: ='summary sheet'!$E$2 -> 120 | J58: =SUM(I58*H58)*G58 -> 0 | K58: 0 | L58: 0 | M58: 0 | N58: =J58 -> 0 | O58: =SUM(G58)*K58 -> 0 | P58: =SUM(L58) -> 0 | Q58: =M58 -> 0 | R58: =SUM(N58:Q58) -> 0 | S58: =(R58/($R$61-$R$60))*SUM($R$64:$R$69,$R$71:$R$72,$R$74,$R$76,$R$78,$R$60)+R58 -> #DIV/0! | T58: =S58/G58 -> #DIV/0! | V58: =IF($K58=0,$X58,$K58) | W58: =IF($E58="",$Z58,$E58) | X58: =IF($F58="","",INDEX('Bobrick Material Pricing 2025'!$A$2:$C$1000,MATCH($F58,'Bobrick Material Pricing 2025'!$A$2:$A$1000,0),3)) | Y58: =IF($F58="","",INDEX('Bobrick Labor Factors'!$A$2:$E$556,MATCH($F58,'Bobrick Labor Factors'!$A$2:$A$556,0),5)) | Z58: =IF($F58="","",INDEX('Bobrick Material Pricing 2025'!$A$2:$C$1000,MATCH($F58,'Bobrick Material Pricing 2025'!$A$2:$A$1000,0),2))
A59: SUBTOTAL | N59: =SUM(N9:N58) -> 0 | O59: =SUM(O9:O58) -> 0 | P59: =SUM(P9:P58) -> 0 | Q59: =SUM(Q9:Q58) -> 0 | R59: =SUM(N59:Q59) -> 0 | S59: =SUM(S9:S58) -> #DIV/0! | U59: =SUM(R9:R58)-R59 -> 0
A60: TAX | R60: =SUM(O59+P59)*U60 -> 0 | U60: ='summary sheet'!E1 -> 0.0975
A61: CATEGORY SUBTOTAL | R61: =SUM(R59:R60) -> 0
N62: DESCRIPTION | O62: QUANTITY | P62: U/M | Q62: UNIT COST
N64: Lifts & Rentals | O64: 1 | P64: LS | Q64: 0 | R64: =SUM(O64)*Q64 -> 0
N65: Superintendent | O65: 1 | P65: LS | Q65: =N59*0.1 -> 0 | R65: =SUM(O65)*Q65 -> 0
N66: Misc. Hardware & Tools | O66: =IF($N$59=0,"0",1) -> 0 | P66: LS | Q66: =O59*0.02 -> 0 | R66: =SUM(O66)*Q66 -> 0
N67: Field Verification | O67: 0 | P67: Days | Q67: ='summary sheet'!$E$2*8 -> 960 | R67: =SUM(O67)*Q67 -> 0
N68: Receiving & Cleanup | O68: 0 | P68: Days | Q68: ='summary sheet'!$E$2*8 -> 960 | R68: =SUM(O68)*Q68 -> 0
N69: Parking | O69: 1 | P69: Days | Q69: 0 | R69: =SUM(O69)*Q69 -> 0
N70: SUB TOTAL | R70: =SUM(R61,R64:R69) -> 0
N71: ESCALATION (%): | Q71: ='summary sheet'!$E$3 -> 0.03 | R71: =SUM(O59)*Q71 -> 0
N72: OVERHEAD (%): | Q72: ='summary sheet'!$E$4 -> 0.08 | R72: =SUM(R70)*Q72 -> 0
N73: SUB TOTAL | R73: =SUM(R70:R72) -> 0
N74: FEE (%): | Q74: 0.12 | R74: =SUM(R73)*Q74 -> 0
N75: SUB TOTAL | R75: =SUM(R73:R74) -> 0 | S75: =SUM(S9:S58) -> #DIV/0!
N76: BOND (%): | Q76: ='summary sheet'!$E$5 -> 0.006 | R76: =SUM(R75)*Q76 -> 0
N77: SUB TOTAL | R77: =SUM(R75:R76) -> 0 | S77: =R79-S75 -> #DIV/0!
N78: INSURANCE (%): | Q78: ='summary sheet'!$E$6 -> 0.0125 | R78: =SUM(R77)*Q78 -> 0
...

Sheet Toilet Compartments
A1: ='summary sheet'!A1 -> PROJECT:
A2: ='summary sheet'!A2:A2 -> SHIP TO:
A3: {=CONCATENATE("SCOPE: ",MID(CELL("filename",A1),FIND("]",CELL("filename",A1))+1,255))} -> SCOPE: Toilet Compartments
A4: ='summary sheet'!A4 -> BID INFO:
A5: ='summary sheet'!A5 -> 45940.587
J6: * * * * * * * * * * * UNIT COST * * * * * * * * * * * * * * * | N6: * * * * * * * * * * * * * * TOTAL COST * * * * * * * * * * * * * * * * * * | U6: Remarks
B7: SPEC No. | C7: SPEC TITLE | D7: PLAN CALLOUT | E7: DESCRIPTION | F7: MODEL NUMBER | G7: ITEM QUANTITY | H7: LABOR FACTOR | I7: LABOR RATE | J7: LABOR | K7: MATERIAL | L7: FREIGHT | M7: SUB | N7: LABOR | O7: MATERIAL | P7: FREIGHT | Q7: SUB | R7: TOTAL | S7: BREAKOUT COST | T7: BREAKOUT UNIT PRICE
M8: CONTRACT | Q8: CONTRACT
A9: 1 | I9: ='summary sheet'!$E$2 -> 120 | J9: =SUM(I9*H9)*G9 -> 0 | K9: 0 | L9: 0 | M9: 0 | N9: =J9 -> 0 | O9: =SUM(G9)*K9 -> 0 | P9: =SUM(L9) -> 0 | Q9: =M9 -> 0 | R9: =SUM(N9:Q9) -> 0 | S9: =(R9/($R$61-$R$60))*SUM($R$64:$R$69,$R$71:$R$72,$R$74,$R$76,$R$78,$R$60)+R9 -> #DIV/0! | T9: =S9/G9 -> #DIV/0!
A10: 2 | I10: ='summary sheet'!$E$2 -> 120 | J10: =SUM(I10*H10)*G10 -> 0 | K10: 0 | L10: 0 | M10: 0 | N10: =J10 -> 0 | O10: =SUM(G10)*K10 -> 0 | P10: =SUM(L10) -> 0 | Q10: =M10 -> 0 | R10: =SUM(N10:Q10) -> 0 | S10: =(R10/($R$61-$R$60))*SUM($R$64:$R$69,$R$71:$R$72,$R$74,$R$76,$R$78,$R$60)+R10 -> #DIV/0! | T10: =S10/G10 -> #DIV/0!
A11: 3 | I11: ='summary sheet'!$E$2 -> 120 | J11: =SUM(I11*H11)*G11 -> 0 | K11: 0 | L11: 0 | M11: 0 | N11: =J11 -> 0 | O11: =SUM(G11)*K11 -> 0 | P11: =SUM(L11) -> 0 | Q11: =M11 -> 0 | R11: =SUM(N11:Q11) -> 0 | S11: =(R11/($R$61-$R$60))*SUM($R$64:$R$69,$R$71:$R$72,$R$74,$R$76,$R$78,$R$60)+R11 -> #DIV/0! | T11: =S11/G11 -> #DIV/0!
A12: 4 | I12: ='summary sheet'!$E$2 -> 120 | J12: =SUM(I12*H12)*G12 -> 0 | K12: 0 | L12: 0 | M12: 0 | N12: =J12 -> 0 | O12: =SUM(G12)*K12 -> 0 | P12: =SUM(L12) -> 0 | Q12: =M12 -> 0 | R12: =SUM(N12:Q12) -> 0 | S12: =(R12/($R$61-$R$60))*SUM($R$64:$R$69,$R$71:$R$72,$R$74,$R$76,$R$78,$R$60)+R12 -> #DIV/0! | T12: =S12/G12 -> #DIV/0!
A13: 5 | I13: ='summary sheet'!$E$2 -> 120 | J13: =SUM(I13*H13)*G13 -> 0 | K13: 0 | L13: 0 | M13: 0 | N13: =J13 -> 0 | O13: =SUM(G13)*K13 -> 0 | P13: =SUM(L13) -> 0 | Q13: =M13 -> 0 | R13: =SUM(N13:Q13) -> 0 | S13: =(R13/($R$61-$R$60))*SUM($R$64:$R$69,$R$71:$R$72,$R$74,$R$76,$R$78,$R$60)+R13 -> #DIV/0! | T13: =S13/G13 -> #DIV/0!
A14: 6 | I14: ='summary sheet'!$E$2 -> 120 | J14: =SUM(I14*H14)*G14 -> 0 | K14: 0 | L14: 0 | M14: 0 | N14: =J14 -> 0 | O14: =SUM(G14)*K14 -> 0 | P14: =SUM(L14) -> 0 | Q14: =M14 -> 0 | R14: =SUM(N14:Q14) -> 0 | S14: =(R14/($R$61-$R$60))*SUM($R$64:$R$69,$R$71:$R$72,$R$74,$R$76,$R$78,$R$60)+R14 -> #DIV/0! | T14: =S14/G14 -> #DIV/0!
A15: 7 | I15: ='summary sheet'!$E$2 -> 120 | J15: =SUM(I15*H15)*G15 -> 0 | K15: 0 | L15: 0 | M15: 0 | N15: =J15 -> 0 | O15: =SUM(G15)*K15 -> 0 | P15: =SUM(L15) -> 0 | Q15: =M15 -> 0 | R15: =SUM(N15:Q15) -> 0 | S15: =(R15/($R$61-$R$60))*SUM($R$64:$R$69,$R$71:$R$72,$R$74,$R$76,$R$78,$R$60)+R15 -> #DIV/0! | T15: =S15/G15 -> #DIV/0!
A16: 8 | I16: ='summary sheet'!$E$2 -> 120 | J16: =SUM(I16*H16)*G16 -> 0 | K16: 0 | L16: 0 | M16: 0 | N16: =J16 -> 0 | O16: =SUM(G16)*K16 -> 0 | P16: =SUM(L16) -> 0 | Q16: =M16 -> 0 | R16: =SUM(N16:Q16) -> 0 | S16: =(R16/($R$61-$R$60))*SUM($R$64:$R$69,$R$71:$R$72,$R$74,$R$76,$R$78,$R$60)+R16 -> #DIV/0! | T16: =S16/G16 -> #DIV/0!
A17: 9 | I17: ='summary sheet'!$E$2 -> 120 | J17: =SUM(I17*H17)*G17 -> 0 | K17: 0 | L17: 0 | M17: 0 | N17: =J17 -> 0 | O17: =SUM(G17)*K17 -> 0 | P17: =SUM(L17) -> 0 | Q17: =M17 -> 0 | R17: =SUM(N17:Q17) -> 0 | S17: =(R17/($R$61-$R$60))*SUM($R$64:$R$69,$R$71:$R$72,$R$74,$R$76,$R$78,$R$60)+R17 -> #DIV/0! | T17: =S17/G17 -> #DIV/0!
A18: 10 | I18: ='summary sheet'!$E$2 -> 120 | J18: =SUM(I18*H18)*G18 -> 0 | K18: 0 | L18: 0 | M18: 0 | N18: =J18 -> 0 | O18: =SUM(G18)*K18 -> 0 | P18: =SUM(L18) -> 0 | Q18: =M18 -> 0 | R18: =SUM(N18:Q18) -> 0 | S18: =(R18/($R$61-$R$60))*SUM($R$64:$R$69,$R$71:$R$72,$R$74,$R$76,$R$78,$R$60)+R18 -> #DIV/0! | T18: =S18/G18 -> #DIV/0!
A19: 11 | I19: ='summary sheet'!$E$2 -> 120 | J19: =SUM(I19*H19)*G19 -> 0 | K19: 0 | L19: 0 | M19: 0 | N19: =J19 -> 0 | O19: =SUM(G19)*K19 -> 0 | P19: =SUM(L19) -> 0 | Q19: =M19 -> 0 | R19: =SUM(N19:Q19) -> 0 | S19: =(R19/($R$61-$R$60))*SUM($R$64:$R$69,$R$71:$R$72,$R$74,$R$76,$R$78,$R$60)+R19 -> #DIV/0! | T19: =S19/G19 -> #DIV/0!
A20: 12 | I20: ='summary sheet'!$E$2 -> 120 | J20: =SUM(I20*H20)*G20 -> 0 | K20: 0 | L20: 0 | M20: 0 | N20: =J20 -> 0 | O20: =SUM(G20)*K20 -> 0 | P20: =SUM(L20) -> 0 | Q20: =M20 -> 0 | R20: =SUM(N20:Q20) -> 0 | S20: =(R20/($R$61-$R$60))*SUM($R$64:$R$69,$R$71:$R$72,$R$74,$R$76,$R$78,$R$60)+R20 -> #DIV/0! | T20: =S20/G20 -> #DIV/0!
... A58: 50 | I58: ='summary sheet'!$E$2 -> 120 | J58: =SUM(I58*H58)*G58 -> 0 | K58: 0 | L58: 0 | M58: 0 | N58: =J58 -> 0 | O58: =SUM(G58)*K58 -> 0 | P58: =SUM(L58) -> 0 | Q58: =M58 -> 0 | R58: =SUM(N58:Q58) -> 0 | S58: =(R58/($R$61-$R$60))*SUM($R$64:$R$69,$R$71:$R$72,$R$74,$R$76,$R$78,$R$60)+R58 -> #DIV/0! | T58: =S58/G58 -> #DIV/0!
A59: SUBTOTAL | N59: =SUM(N9:N58) -> 0 | O59: =SUM(O9:O58) -> 0 | P59: =SUM(P9:P58) -> 0 | Q59: =SUM(Q9:Q58) -> 0 | R59: =SUM(N59:Q59) -> 0 | S59: =SUM(S9:S58) -> #DIV/0! | U59: =SUM(R9:R58)-R59 -> 0
A60: TAX | R60: =SUM(O59+P59)*U60 -> 0 | U60: ='summary sheet'!E1 -> 0.0975
A61: CATEGORY SUBTOTAL | R61: =SUM(R59:R60) -> 0
N62: DESCRIPTION | O62: QUANTITY | P62: U/M | Q62: UNIT COST
N64: Lifts & Rentals | O64: 1 | P64: LS | Q64: 0 | R64: =SUM(O64)*Q64 -> 0
N65: Superintendent | O65: 1 | P65: LS | Q65: =N59*0.1 -> 0 | R65: =SUM(O65)*Q65 -> 0
N66: Misc. Hardware & Tools | O66: =IF($N$59=0,"0",1) -> 0 | P66: LS | Q66: =O59*0.02 -> 0 | R66: =SUM(O66)*Q66 -> 0
N67: Field Verification | O67: 0 | P67: Days | Q67: ='summary sheet'!$E$2*8 -> 960 | R67: =SUM(O67)*Q67 -> 0
N68: Receiving & Cleanup | O68: 0 | P68: Days | Q68: ='summary sheet'!$E$2*8 -> 960 | R68: =SUM(O68)*Q68 -> 0
N69: Parking | O69: =N59/655 -> 0 | P69: Days | Q69: 0 | R69: =SUM(O69)*Q69 -> 0
N70: SUB TOTAL | R70: =SUM(R61,R64:R69) -> 0
N71: ESCALATION (%): | Q71: ='summary sheet'!$E$3 -> 0.03 | R71: =SUM(O59)*Q71 -> 0
N72: OVERHEAD (%): | Q72: ='summary sheet'!$E$4 -> 0.08 | R72: =SUM(R70)*Q72 -> 0
N73: SUB TOTAL | R73: =SUM(R70:R72) -> 0
N74: FEE (%): | Q74: 0.12 | R74: =SUM(R73)*Q74 -> 0
N75: SUB TOTAL | R75: =SUM(R73:R74) -> 0 | S75: =SUM(S9:S58) -> #DIV/0!
N76: BOND (%): | Q76: ='summary sheet'!$E$5 -> 0.006 | R76: =SUM(R75)*Q76 -> 0
N77: SUB TOTAL | R77: =SUM(R75:R76) -> 0 | S77: =R75-S75 -> #DIV/0!
N78: INSURANCE (%): | Q78: ='summary sheet'!$E$6 -> 0.0125 | R78: =SUM(R77)*Q78 -> 0
...

Sheet Bobrick Material Pricing 2025
A1: Model | B1: Description | C1: US Net | D1: Upload Notes: | E1: 09.29.25 - Bobrick/Koala pricing updated on 9.29.25 from newly provided price list from PBS. Markup was reduced to 10% from 20% per KR. Initially had 20% markup in anticipation of getting NBS Bobrick Account.
A2: B-40 | B2: Soap Dispenser, 2-Tone Black/Grey ABS – 40-fl. oz. | C2: 29.535
A3: B-42 | B3: Soap Dispenser, All Black ABS – 40-fl. oz. | C3: 29.04
A4: B-211 | B4: Heavy-Duty Clothes Hook with Exposed Mounting | C4: 21.45
A5: B-212 | B5: Clothes Hook with Bumper | C5: 9.9
A6: B-221 | B6: Toilet Seat Cover Dispenser, Stainless Steel | C6: 36.135
A7: B-233 | B7: Clothes Hook | C7: 15.345
A8: B-253 | B8: Surface-Mounted Roll-Paper-Towel Dispenser | C8: 45.54
A9: B-254 | B9: Sanitary Napkin Disposal, 1.2-Gal. | C9: 125.895
A10: B-262 | B10: Paper Towel Dispenser, 400 C-Fold or Multifold, Tumbler Lock | C10: 55.605
A11: B-263 | B11: Paper Towel Dispenser, Stainless Steel – Singlefold | C11: 136.62
A12: B-264 | B12: Single-Roll Toilet Tissue Dispenser | C12: 17.325
A13: B-265 | B13: Double-Roll Toilet Tissue Dispenser | C13: 28.545
... A578: B-8892 | B578: NEW: Designer Series Automatic Faucet, Matte Black | C578: 612.7
A579: B-150CX18.MBLK | B579: 18" Straight Grab Bar with Concealed Flange, Matte Black
A580: B-150CX24.MBLK | B580: 24" Straight Grab Bar with Concealed Flange, Matte Black
A581: B-150CX36.MBLK | B581: 36" Straight Grab Bar with Concealed Flange, Matte Black
A582: B-150CX42.MBLK | B582: 42" Straight Grab Bar with Concealed Flange, Matte Black
A583: B-150CX48.MBLK | B583: 48" Straight Grab Bar with Concealed Flange, Matte Black
A584: B-2012.MBLK | B584: Automatic Wall-Mounted Soap Dispenser, 30-fl. oz., Matte Black | C584: 194.865
A585: B-2013.MBLK | B585: Automatic Wall-Mounted Foam Soap Dispenser, 27-fl. Oz, Matte Black | C585: 226.05
A586: B-221.MBLK | B586: Toilet Seat Cover Dispenser, Matte Black | C586: 104.28
A587: B-104 2448.MBLK | B587: NEW: Pill Shaped Matte Black Mirror 24" x 48" | C587: 662.805
A588: B-167 2436.MBLK | B588: NEW: LED Matte Black Mirror 24" x 36" | C588: 669.9
A589: B-290 1830.MBLK | B589: 18" Wide x 30" High, Matte Black | C589: 149.16
A590: B-290 1836.MBLK | B590: 18" Wide x 36" High, Matte Black | C590: 156.09
A591: B-290 2430.MBLK | B591: 24" Wide x 30" High, Matte Black | C591: 194.205
A592: B-290 2436.MBLK | B592: 24" Wide x 36" High, Matte Black | C592: 196.515
A593: B-290 2448.MBLK | B593: 24" Wide x 48" High, Matte Black | C593: 298.155
A594: B-290 2460.MBLK | B594: 24" Wide x 60" High, Matte Black | C594: 353.595
A595: B-290 2472.MBLK | B595: 24" Wide x 72" High, Matte Black | C595: 412.5
... A711: KB977-09 | B711: KidSitter (Brown with Grey Legs) | C711: 242.59796

Sheet Bobrick Labor Factors
A1: Model | B1: Model Description | C1: Swinerton Net | D1: Labor in Minute | E1: Labor Multiplier
A2: B-155 | B2: Liquidmate® Wall-Mounted Soap Dispenser | C2: 15.228828 | D2: 15 | E2: =D2/60 -> 0.25
A3: B-156 | B3: Liquidmate® Surface-Mounted Soap Dispenser | C3: 10.025645 | D3: 15 | E3: =D3/60 -> 0.25
A4: B-1556 1824 | B4: Frameless Mirror 18x24 | C4: 60.280777 | D4: 30 | E4: =D4/60 -> 0.5
A5: B-1556 1830 | B5: Frameless Mirror 18x30 | C5: 76.905581 | D5: 30 | E5: =D5/60 -> 0.5
A6: B-1556 2436 | B6: Frameless Mirror 24x36 | C6: 110.91663 | D6: 30 | E6: =D6/60 -> 0.5
A7: B-164 2436 | B7: Reversible LED Backlit Mirror 24x36 | C7: 374.50226 | D7: 30 | E7: =D7/60 -> 0.5
A8: B-164 2442 | B8: Reversible LED Backlit Mirror 24x42 | C8: 441.63601 | D8: 30 | E8: =D8/60 -> 0.5
A9: B-165 1824 | B9: Channel-Frame Mirror 18x24 | C9: 31.726725 | D9: 30 | E9: =D9/60 -> 0.5
A10: B-165 1830 | B10: Channel-Frame Mirror 18x30 | C10: 34.645584 | D10: 30 | E10: =D10/60 -> 0.5
A11: B-165 1836 | B11: Channel-Frame Mirror 18x36 | C11: 38.960418 | D11: 30 | E11: =D11/60 -> 0.5
A12: B-165 2430 | B12: Channel-Frame Mirror 24x30 | C12: 48.351529 | D12: 30 | E12: =D12/60 -> 0.5
A13: B-165 2436 | B13: Channel-Frame Mirror 24x36 | C13: 49.239877 | D13: 30 | E13: =D13/60 -> 0.5
A14: B-165 2448 | B14: Channel-Frame Mirror 24x48 | C14: 72.210026 | D14: 30 | E14: =D14/60 -> 0.5
... A457: B-985 | B457: Vandal-Resistant Clothes Hook Strip | C457: 326.15073 | D457: 15 | E457: =D457/60 -> 0.25
A458: KB102-00 | B458: Child Protection Seat (Cream) | D458: 30 | E458: =D458/60 -> 0.5
A459: KB102-01 | B459: Child Protection Seat (Grey) | D459: 30 | E459: =D459/60 -> 0.5
A460: KB105-01 | B460: Designer High Chair (Grey) | D460: 30 | E460: =D460/60 -> 0.5
A461: KB105-01-KD | B461: Designer High Chair (Grey) Knockdown | D461: 30 | E461: =D461/60 -> 0.5
A462: KB105-02 | B462: Designer High Chair (Black) | D462: 30 | E462: =D462/60 -> 0.5
A463: KB105-02-KD | B463: Designer High Chair (Black) Knockdown | D463: 30 | E463: =D463/60 -> 0.5
A464: KB105-03 | B464: Designer High Chair (Red) | D464: 30 | E464: =D464/60 -> 0.5
A465: KB105-03-KD | B465: Designer High Chair (Red) Knockdown | D465: 30 | E465: =D465/60 -> 0.5
A466: KB105-09 | B466: Designer High Chair (Brown) | D466: 30 | E466: =D466/60 -> 0.5
A467: KB105-09-KD | B467: Designer High Chair (Brown) Knockdown | D467: 30 | E467: =D467/60 -> 0.5
A468: KB110-SSRE | B468: SS Horizontal Recessed-Mounted Changing Station | D468: 30 | E468: =D468/60 -> 0.5
A469: KB110-SSWM | B469: SS Horizontal Surface-Mounted Changing Station | D469: 30 | E469: =D469/60 -> 0.5
... A556: KB977-09 | B556: KidSitter Grey Legs/Brown Seat | D556: 30 | E556: =D556/60 -> 0.5

Sheet Wall Protection
A1: ='summary sheet'!A1 -> PROJECT:
A2: ='summary sheet'!A2:A2 -> SHIP TO:
A3: {=CONCATENATE("SCOPE: ",MID(CELL("filename",A1),FIND("]",CELL("filename",A1))+1,255))} -> SCOPE: Wall Protection
A4: ='summary sheet'!A4 -> BID INFO:
A5: ='summary sheet'!A5 -> 45940.587
J6: * * * * * * * * * * * UNIT COST * * * * * * * * * * * * * * * | N6: * * * * * * * * * * * * * * TOTAL COST * * * * * * * * * * * * * * * * * * | U6: Remarks
B7: SPEC No. | C7: SPEC TITLE | D7: PLAN CALLOUT | E7: DESCRIPTION | F7: MODEL NUMBER | G7: ITEM QUANTITY | H7: LABOR FACTOR | I7: LABOR RATE | J7: LABOR | K7: MATERIAL | L7: FREIGHT | M7: SUB | N7: LABOR | O7: MATERIAL | P7: FREIGHT | Q7: SUB | R7: TOTAL | S7: BREAKOUT COST | T7: BREAKOUT UNIT PRICE
M8: CONTRACT | Q8: CONTRACT
A9: 1 | I9: ='summary sheet'!$E$2 -> 120 | J9: =SUM(H9*I9)*G9 -> 0 | K9: 0 | L9: 0 | M9: 0 | N9: =J9 -> 0 | O9: =SUM(G9)*K9 -> 0 | P9: =SUM(L9) -> 0 | Q9: =M9 -> 0 | R9: =SUM(N9:Q9) -> 0 | S9: =(R9/($R$61-$R$60))*SUM($R$64:$R$69,$R$71:$R$72,$R$74,$R$76,$R$78,$R$60)+R9 -> #DIV/0! | T9: =S9/G9 -> #DIV/0!
A10: 2 | I10: ='summary sheet'!$E$2 -> 120 | J10: =SUM(H10*I10)*G10 -> 0 | K10: 0 | L10: 0 | M10: 0 | N10: =J10 -> 0 | O10: =SUM(G10)*K10 -> 0 | P10: =SUM(L10) -> 0 | Q10: =M10 -> 0 | R10: =SUM(N10:Q10) -> 0 | S10: =(R10/($R$61-$R$60))*SUM($R$64:$R$69,$R$71:$R$72,$R$74,$R$76,$R$78,$R$60)+R10 -> #DIV/0! | T10: =S10/G10 -> #DIV/0!
A11: 3 | I11: ='summary sheet'!$E$2 -> 120 | J11: =SUM(H11*I11)*G11 -> 0 | K11: 0 | L11: 0 | M11: 0 | N11: =J11 -> 0 | O11: =SUM(G11)*K11 -> 0 | P11: =SUM(L11) -> 0 | Q11: =M11 -> 0 | R11: =SUM(N11:Q11) -> 0 | S11: =(R11/($R$61-$R$60))*SUM($R$64:$R$69,$R$71:$R$72,$R$74,$R$76,$R$78,$R$60)+R11 -> #DIV/0! | T11: =S11/G11 -> #DIV/0!
A12: 4 | I12: ='summary sheet'!$E$2 -> 120 | J12: =SUM(H12*I12)*G12 -> 0 | K12: 0 | L12: 0 | M12: 0 | N12: =J12 -> 0 | O12: =SUM(G12)*K12 -> 0 | P12: =SUM(L12) -> 0 | Q12: =M12 -> 0 | R12: =SUM(N12:Q12) -> 0 | S12: =(R12/($R$61-$R$60))*SUM($R$64:$R$69,$R$71:$R$72,$R$74,$R$76,$R$78,$R$60)+R12 -> #DIV/0! | T12: =S12/G12 -> #DIV/0!
A13: 5 | I13: ='summary sheet'!$E$2 -> 120 | J13: =SUM(H13*I13)*G13 -> 0 | K13: 0 | L13: 0 | M13: 0 | N13: =J13 -> 0 | O13: =SUM(G13)*K13 -> 0 | P13: =SUM(L13) -> 0 | Q13: =M13 -> 0 | R13: =SUM(N13:Q13) -> 0 | S13: =(R13/($R$61-$R$60))*SUM($R$64:$R$69,$R$71:$R$72,$R$74,$R$76,$R$78,$R$60)+R13 -> #DIV/0! | T13: =S13/G13 -> #DIV/0!
A14: 6 | I14: ='summary sheet'!$E$2 -> 120 | J14: =SUM(H14*I14)*G14 -> 0 | K14: 0 | L14: 0 | M14: 0 | N14: =J14 -> 0 | O14: =SUM(G14)*K14 -> 0 | P14: =SUM(L14) -> 0 | Q14: =M14 -> 0 | R14: =SUM(N14:Q14) -> 0 | S14: =(R14/($R$61-$R$60))*SUM($R$64:$R$69,$R$71:$R$72,$R$74,$R$76,$R$78,$R$60)+R14 -> #DIV/0! | T14: =S14/G14 -> #DIV/0!
A15: 7 | I15: ='summary sheet'!$E$2 -> 120 | J15: =SUM(H15*I15)*G15 -> 0 | K15: 0 | L15: 0 | M15: 0 | N15: =J15 -> 0 | O15: =SUM(G15)*K15 -> 0 | P15: =SUM(L15) -> 0 | Q15: =M15 -> 0 | R15: =SUM(N15:Q15) -> 0 | S15: =(R15/($R$61-$R$60))*SUM($R$64:$R$69,$R$71:$R$72,$R$74,$R$76,$R$78,$R$60)+R15 -> #DIV/0! | T15: =S15/G15 -> #DIV/0!
A16: 8 | I16: ='summary sheet'!$E$2 -> 120 | J16: =SUM(H16*I16)*G16 -> 0 | K16: 0 | L16: 0 | M16: 0 | N16: =J16 -> 0 | O16: =SUM(G16)*K16 -> 0 | P16: =SUM(L16) -> 0 | Q16: =M16 -> 0 | R16: =SUM(N16:Q16) -> 0 | S16: =(R16/($R$61-$R$60))*SUM($R$64:$R$69,$R$71:$R$72,$R$74,$R$76,$R$78,$R$60)+R16 -> #DIV/0! | T16: =S16/G16 -> #DIV/0!
A17: 9 | I17: ='summary sheet'!$E$2 -> 120 | J17: =SUM(H17*I17)*G17 -> 0 | K17: 0 | L17: 0 | M17: 0 | N17: =J17 -> 0 | O17: =SUM(G17)*K17 -> 0 | P17: =SUM(L17) -> 0 | Q17: =M17 -> 0 | R17: =SUM(N17:Q17) -> 0 | S17: =(R17/($R$61-$R$60))*SUM($R$64:$R$69,$R$71:$R$72,$R$74,$R$76,$R$78,$R$60)+R17 -> #DIV/0! | T17: =S17/G17 -> #DIV/0!
A18: 10 | I18: ='summary sheet'!$E$2 -> 120 | J18: =SUM(H18*I18)*G18 -> 0 | K18: 0 | L18: 0 | M18: 0 | N18: =J18 -> 0 | O18: =SUM(G18)*K18 -> 0 | P18: =SUM(L18) -> 0 | Q18: =M18 -> 0 | R18: =SUM(N18:Q18) -> 0 | S18: =(R18/($R$61-$R$60))*SUM($R$64:$R$69,$R$71:$R$72,$R$74,$R$76,$R$78,$R$60)+R18 -> #DIV/0! | T18: =S18/G18 -> #DIV/0!
A19: 11 | I19: ='summary sheet'!$E$2 -> 120 | J19: =SUM(H19*I19)*G19 -> 0 | K19: 0 | L19: 0 | M19: 0 | N19: =J19 -> 0 | O19: =SUM(G19)*K19 -> 0 | P19: =SUM(L19) -> 0 | Q19: =M19 -> 0 | R19: =SUM(N19:Q19) -> 0 | S19: =(R19/($R$61-$R$60))*SUM($R$64:$R$69,$R$71:$R$72,$R$74,$R$76,$R$78,$R$60)+R19 -> #DIV/0! | T19: =S19/G19 -> #DIV/0!
A20: 12 | I20: ='summary sheet'!$E$2 -> 120 | J20: =SUM(H20*I20)*G20 -> 0 | K20: 0 | L20: 0 | M20: 0 | N20: =J20 -> 0 | O20: =SUM(G20)*K20 -> 0 | P20: =SUM(L20) -> 0 | Q20: =M20 -> 0 | R20: =SUM(N20:Q20) -> 0 | S20: =(R20/($R$61-$R$60))*SUM($R$64:$R$69,$R$71:$R$72,$R$74,$R$76,$R$78,$R$60)+R20 -> #DIV/0! | T20: =S20/G20 -> #DIV/0!
... A58: 50 | I58: ='summary sheet'!$E$2 -> 120 | J58: =SUM(H58*I58)*G58 -> 0 | K58: 0 | L58: 0 | M58: 0 | N58: =J58 -> 0 | O58: =SUM(G58)*K58 -> 0 | P58: =SUM(L58) -> 0 | Q58: =M58 -> 0 | R58: =SUM(N58:Q58) -> 0 | S58: =(R58/($R$61-$R$60))*SUM($R$64:$R$69,$R$71:$R$72,$R$74,$R$76,$R$78,$R$60)+R58 -> #DIV/0! | T58: =S58/G58 -> #DIV/0!
A59: SUBTOTAL | N59: =SUM(N9:N58) -> 0 | O59: =SUM(O9:O58) -> 0 | P59: =SUM(P9:P58) -> 0 | Q59: =SUM(Q9:Q58) -> 0 | R59: =SUM(N59:Q59) -> 0 | S59: =SUM(S39:S58) -> #DIV/0! | U59: =SUM(R39:R58)-R59 -> 0
A60: TAX | R60: =SUM(O59+P59)*U60 -> 0 | U60: ='summary sheet'!E1 -> 0.0975
A61: CATEGORY SUBTOTAL | R61: =SUM(R59:R60) -> 0
N62: DESCRIPTION | O62: QUANTITY | P62: U/M | Q62: UNIT COST
N64: Lifts & Rentals | O64: 1 | P64: LS | Q64: 0 | R64: =SUM(O64)*Q64 -> 0
N65: Superintendent | O65: 1 | P65: LS | Q65: =N59*0.1 -> 0 | R65: =SUM(O65)*Q65 -> 0
N66: Misc. Hardware & Tools | O66: =IF($N$59=0,"0",1) -> 0 | P66: LS | Q66: =O59*0.02 -> 0 | R66: =SUM(O66)*Q66 -> 0
N67: Field Verification | O67: 0 | P67: Days | Q67: ='summary sheet'!$E$2*8 -> 960 | R67: =SUM(O67)*Q67 -> 0
N68: Receiving & Cleanup | O68: 0 | P68: Days | Q68: ='summary sheet'!$E$2*8 -> 960 | R68: =SUM(O68)*Q68 -> 0
N69: Parking | O69: =N59/655 -> 0 | P69: Days | Q69: 0 | R69: =SUM(O69)*Q69 -> 0
N70: SUB TOTAL | R70: =SUM(R61,R64:R69) -> 0
N71: ESCALATION (%): | Q71: ='summary sheet'!$E$3 -> 0.03 | R71: =SUM(O59)*Q71 -> 0
N72: OVERHEAD (%): | Q72: ='summary sheet'!$E$4 -> 0.08 | R72: =SUM(R70)*Q72 -> 0
N73: SUB TOTAL | R73: =SUM(R70:R72) -> 0
N74: FEE (%): | Q74: 0.12 | R74: =SUM(R73)*Q74 -> 0
N75: SUB TOTAL | R75: =SUM(R73:R74) -> 0 | S75: =SUM(S9:S58) -> #DIV/0!
N76: BOND (%): | Q76: ='summary sheet'!$E$5 -> 0.006 | R76: =SUM(R75)*Q76 -> 0
N77: SUB TOTAL | R77: =SUM(R75:R76) -> 0 | S77: =R75-S75 -> #DIV/0!
N78: INSURANCE (%): | Q78: ='summary sheet'!$E$6 -> 0.0125 | R78: =SUM(R77)*Q78 -> 0
...

Sheet Appliances
A1: ='summary sheet'!A1 -> PROJECT:
A2: ='summary sheet'!A2:A2 -> SHIP TO:
A3: {=CONCATENATE("SCOPE: ",MID(CELL("filename",A1),FIND("]",CELL("filename",A1))+1,255))} -> SCOPE: Appliances
A4: ='summary sheet'!A4 -> BID INFO:
A5: ='summary sheet'!A5 -> 45940.587
J6: * * * * * * * * * * * UNIT COST * * * * * * * * * * * * * * * | N6: * * * * * * * * * * * * * * TOTAL COST * * * * * * * * * * * * * * * * * * | U6: Remarks
B7: SPEC No. | C7: SPEC TITLE | D7: PLAN CALLOUT | E7: DESCRIPTION | F7: MODEL NUMBER | G7: ITEM QUANTITY | H7: LABOR FACTOR | I7: LABOR RATE | J7: LABOR | K7: MATERIAL | L7: FREIGHT | M7: SUB | N7: LABOR | O7: MATERIAL | P7: FREIGHT | Q7: SUB | R7: TOTAL | S7: BREAKOUT COST | T7: BREAKOUT UNIT PRICE
M8: CONTRACT | Q8: CONTRACT
A9: 1 | I9: ='summary sheet'!$E$2 -> 120 | J9: =SUM(I9*H9)*G9 -> 0 | K9: 0 | L9: 0 | M9: 0 | N9: =J9 -> 0 | O9: =SUM(G9)*K9 -> 0 | P9: =SUM(L9) -> 0 | Q9: =SUM(G9)*M9 -> 0 | R9: =SUM(N9:Q9) -> 0 | S9: =(R9/($R$61-$R$60))*SUM($R$64:$R$69,$R$71:$R$72,$R$74,$R$76,$R$78,$R$60)+R9 -> #DIV/0! | T9: =S9/G9 -> #DIV/0!
A10: 2 | I10: ='summary sheet'!$E$2 -> 120 | J10: =SUM(I10*H10)*G10 -> 0 | K10: 0 | L10: 0 | M10: 0 | N10: =J10 -> 0 | O10: =SUM(G10)*K10 -> 0 | P10: =SUM(L10) -> 0 | Q10: =SUM(G10)*M10 -> 0 | R10: =SUM(N10:Q10) -> 0 | S10: =(R10/($R$61-$R$60))*SUM($R$64:$R$69,$R$71:$R$72,$R$74,$R$76,$R$78,$R$60)+R10 -> #DIV/0! | T10: =S10/G10 -> #DIV/0!
A11: 3 | I11: ='summary sheet'!$E$2 -> 120 | J11: =SUM(I11*H11)*G11 -> 0 | K11: 0 | L11: 0 | M11: 0 | N11: =J11 -> 0 | O11: =SUM(G11)*K11 -> 0 | P11: =SUM(L11) -> 0 | Q11: =SUM(G11)*M11 -> 0 | R11: =SUM(N11:Q11) -> 0 | S11: =(R11/($R$61-$R$60))*SUM($R$64:$R$69,$R$71:$R$72,$R$74,$R$76,$R$78,$R$60)+R11 -> #DIV/0! | T11: =S11/G11 -> #DIV/0!
A12: 4 | I12: ='summary sheet'!$E$2 -> 120 | J12: =SUM(I12*H12)*G12 -> 0 | K12: 0 | L12: 0 | M12: 0 | N12: =J12 -> 0 | O12: =SUM(G12)*K12 -> 0 | P12: =SUM(L12) -> 0 | Q12: =SUM(G12)*M12 -> 0 | R12: =SUM(N12:Q12) -> 0 | S12: =(R12/($R$61-$R$60))*SUM($R$64:$R$69,$R$71:$R$72,$R$74,$R$76,$R$78,$R$60)+R12 -> #DIV/0! | T12: =S12/G12 -> #DIV/0!
A13: 5 | I13: ='summary sheet'!$E$2 -> 120 | J13: =SUM(I13*H13)*G13 -> 0 | K13: 0 | L13: 0 | M13: 0 | N13: =J13 -> 0 | O13: =SUM(G13)*K13 -> 0 | P13: =SUM(L13) -> 0 | Q13: =SUM(G13)*M13 -> 0 | R13: =SUM(N13:Q13) -> 0 | S13: =(R13/($R$61-$R$60))*SUM($R$64:$R$69,$R$71:$R$72,$R$74,$R$76,$R$78,$R$60)+R13 -> #DIV/0! | T13: =S13/G13 -> #DIV/0!
A14: 6 | I14: ='summary sheet'!$E$2 -> 120 | J14: =SUM(I14*H14)*G14 -> 0 | K14: 0 | L14: 0 | M14: 0 | N14: =J14 -> 0 | O14: =SUM(G14)*K14 -> 0 | P14: =SUM(L14) -> 0 | Q14: =SUM(G14)*M14 -> 0 | R14: =SUM(N14:Q14) -> 0 | S14: =(R14/($R$61-$R$60))*SUM($R$64:$R$69,$R$71:$R$72,$R$74,$R$76,$R$78,$R$60)+R14 -> #DIV/0! | T14: =S14/G14 -> #DIV/0!
A15: 7 | I15: ='summary sheet'!$E$2 -> 120 | J15: =SUM(I15*H15)*G15 -> 0 | K15: 0 | L15: 0 | M15: 0 | N15: =J15 -> 0 | O15: =SUM(G15)*K15 -> 0 | P15: =SUM(L15) -> 0 | Q15: =SUM(G15)*M15 -> 0 | R15: =SUM(N15:Q15) -> 0 | S15: =(R15/($R$61-$R$60))*SUM($R$64:$R$69,$R$71:$R$72,$R$74,$R$76,$R$78,$R$60)+R15 -> #DIV/0! | T15: =S15/G15 -> #DIV/0!
A16: 8 | I16: ='summary sheet'!$E$2 -> 120 | J16: =SUM(I16*H16)*G16 -> 0 | K16: 0 | L16: 0 | M16: 0 | N16: =J16 -> 0 | O16: =SUM(G16)*K16 -> 0 | P16: =SUM(L16) -> 0 | Q16: =SUM(G16)*M16 -> 0 | R16: =SUM(N16:Q16) -> 0 | S16: =(R16/($R$61-$R$60))*SUM($R$64:$R$69,$R$71:$R$72,$R$74,$R$76,$R$78,$R$60)+R16 -> #DIV/0! | T16: =S16/G16 -> #DIV/0!
A17: 9 | I17: ='summary sheet'!$E$2 -> 120 | J17: =SUM(I17*H17)*G17 -> 0 | K17: 0 | L17: 0 | M17: 0 | N17: =J17 -> 0 | O17: =SUM(G17)*K17 -> 0 | P17: =SUM(L17) -> 0 | Q17: =SUM(G17)*M17 -> 0 | R17: =SUM(N17:Q17) -> 0 | S17: =(R17/($R$61-$R$60))*SUM($R$64:$R$69,$R$71:$R$72,$R$74,$R$76,$R$78,$R$60)+R17 -> #DIV/0! | T17: =S17/G17 -> #DIV/0!
A18: 10 | I18: ='summary sheet'!$E$2 -> 120 | J18: =SUM(I18*H18)*G18 -> 0 | K18: 0 | L18: 0 | M18: 0 | N18: =J18 -> 0 | O18: =SUM(G18)*K18 -> 0 | P18: =SUM(L18) -> 0 | Q18: =SUM(G18)*M18 -> 0 | R18: =SUM(N18:Q18) -> 0 | S18: =(R18/($R$61-$R$60))*SUM($R$64:$R$69,$R$71:$R$72,$R$74,$R$76,$R$78,$R$60)+R18 -> #DIV/0! | T18: =S18/G18 -> #DIV/0!
A19: 11 | I19: ='summary sheet'!$E$2 -> 120 | J19: =SUM(I19*H19)*G19 -> 0 | K19: 0 | L19: 0 | M19: 0 | N19: =J19 -> 0 | O19: =SUM(G19)*K19 -> 0 | P19: =SUM(L19) -> 0 | Q19: =SUM(G19)*M19 -> 0 | R19: =SUM(N19:Q19) -> 0 | S19: =(R19/($R$61-$R$60))*SUM($R$64:$R$69,$R$71:$R$72,$R$74,$R$76,$R$78,$R$60)+R19 -> #DIV/0! | T19: =S19/G19 -> #DIV/0!
A20: 12 | I20: ='summary sheet'!$E$2 -> 120 | J20: =SUM(I20*H20)*G20 -> 0 | K20: 0 | L20: 0 | M20: 0 | N20: =J20 -> 0 | O20: =SUM(G20)*K20 -> 0 | P20: =SUM(L20) -> 0 | Q20: =SUM(G20)*M20 -> 0 | R20: =SUM(N20:Q20) -> 0 | S20: =(R20/($R$61-$R$60))*SUM($R$64:$R$69,$R$71:$R$72,$R$74,$R$76,$R$78,$R$60)+R20 -> #DIV/0! | T20: =S20/G20 -> #DIV/0!
... A25: 17 | I25: ='summary sheet'!$E$2 -> 120 | J25: =SUM(I25*H25)*G25 -> 0 | K25: 0 | L25: 0 | M25: 0 | N25: =J25 -> 0 | O25: =SUM(G25)*K25 -> 0 | P25: =SUM(L25) -> 0 | Q25: =SUM(G25)*M25 -> 0 | R25: =SUM(N25:Q25) -> 0 | S25: =(R25/($R$61-$R$60))*SUM($R$64:$R$69,$R$71:$R$72,$R$74,$R$76,$R$78,$R$60)+R25 -> #DIV/0! | T25: =S25/G25 -> #DIV/0!
A26: 18 | I26: ='summary sheet'!$E$2 -> 120 | J26: =SUM(H26*I26)*G26 -> 0 | K26: 0 | L26: 0 | M26: 0 | N26: =J26 -> 0 | O26: =SUM(G26)*K26 -> 0 | P26: =SUM(L26) -> 0 | Q26: =M26 -> 0 | R26: =SUM(N26:Q26) -> 0 | S26: =(R26/($R$61-$R$60))*SUM($R$64:$R$69,$R$71:$R$72,$R$74,$R$76,$R$78,$R$60)+R26 -> #DIV/0! | T26: =S26/G26 -> #DIV/0!
A27: 19 | I27: ='summary sheet'!$E$2 -> 120 | J27: =SUM(H27*I27)*G27 -> 0 | K27: 0 | L27: 0 | M27: 0 | N27: =J27 -> 0 | O27: =SUM(G27)*K27 -> 0 | P27: =SUM(L27) -> 0 | Q27: =M27 -> 0 | R27: =SUM(N27:Q27) -> 0 | S27: =(R27/($R$61-$R$60))*SUM($R$64:$R$69,$R$71:$R$72,$R$74,$R$76,$R$78,$R$60)+R27 -> #DIV/0! | T27: =S27/G27 -> #DIV/0!
A28: 20 | I28: ='summary sheet'!$E$2 -> 120 | J28: =SUM(H28*I28)*G28 -> 0 | K28: 0 | L28: 0 | M28: 0 | N28: =J28 -> 0 | O28: =SUM(G28)*K28 -> 0 | P28: =SUM(L28) -> 0 | Q28: =M28 -> 0 | R28: =SUM(N28:Q28) -> 0 | S28: =(R28/($R$61-$R$60))*SUM($R$64:$R$69,$R$71:$R$72,$R$74,$R$76,$R$78,$R$60)+R28 -> #DIV/0! | T28: =S28/G28 -> #DIV/0!
A29: 21 | I29: ='summary sheet'!$E$2 -> 120 | J29: =SUM(H29*I29)*G29 -> 0 | K29: 0 | L29: 0 | M29: 0 | N29: =J29 -> 0 | O29: =SUM(G29)*K29 -> 0 | P29: =SUM(L29) -> 0 | Q29: =M29 -> 0 | R29: =SUM(N29:Q29) -> 0 | S29: =(R29/($R$61-$R$60))*SUM($R$64:$R$69,$R$71:$R$72,$R$74,$R$76,$R$78,$R$60)+R29 -> #DIV/0! | T29: =S29/G29 -> #DIV/0!
A30: 22 | I30: ='summary sheet'!$E$2 -> 120 | J30: =SUM(H30*I30)*G30 -> 0 | K30: 0 | L30: 0 | M30: 0 | N30: =J30 -> 0 | O30: =SUM(G30)*K30 -> 0 | P30: =SUM(L30) -> 0 | Q30: =M30 -> 0 | R30: =SUM(N30:Q30) -> 0 | S30: =(R30/($R$61-$R$60))*SUM($R$64:$R$69,$R$71:$R$72,$R$74,$R$76,$R$78,$R$60)+R30 -> #DIV/0! | T30: =S30/G30 -> #DIV/0!
A31: 23 | I31: ='summary sheet'!$E$2 -> 120 | J31: =SUM(H31*I31)*G31 -> 0 | K31: 0 | L31: 0 | M31: 0 | N31: =J31 -> 0 | O31: =SUM(G31)*K31 -> 0 | P31: =SUM(L31) -> 0 | Q31: =M31 -> 0 | R31: =SUM(N31:Q31) -> 0 | S31: =(R31/($R$61-$R$60))*SUM($R$64:$R$69,$R$71:$R$72,$R$74,$R$76,$R$78,$R$60)+R31 -> #DIV/0! | T31: =S31/G31 -> #DIV/0!
A32: 24 | I32: ='summary sheet'!$E$2 -> 120 | J32: =SUM(H32*I32)*G32 -> 0 | K32: 0 | L32: 0 | M32: 0 | N32: =J32 -> 0 | O32: =SUM(G32)*K32 -> 0 | P32: =SUM(L32) -> 0 | Q32: =M32 -> 0 | R32: =SUM(N32:Q32) -> 0 | S32: =(R32/($R$61-$R$60))*SUM($R$64:$R$69,$R$71:$R$72,$R$74,$R$76,$R$78,$R$60)+R32 -> #DIV/0! | T32: =S32/G32 -> #DIV/0!
A33: 25 | I33: ='summary sheet'!$E$2 -> 120 | J33: =SUM(H33*I33)*G33 -> 0 | K33: 0 | L33: 0 | M33: 0 | N33: =J33 -> 0 | O33: =SUM(G33)*K33 -> 0 | P33: =SUM(L33) -> 0 | Q33: =M33 -> 0 | R33: =SUM(N33:Q33) -> 0 | S33: =(R33/($R$61-$R$60))*SUM($R$64:$R$69,$R$71:$R$72,$R$74,$R$76,$R$78,$R$60)+R33 -> #DIV/0! | T33: =S33/G33 -> #DIV/0!
A34: 26 | I34: ='summary sheet'!$E$2 -> 120 | J34: =SUM(H34*I34)*G34 -> 0 | K34: 0 | L34: 0 | M34: 0 | N34: =J34 -> 0 | O34: =SUM(G34)*K34 -> 0 | P34: =SUM(L34) -> 0 | Q34: =M34 -> 0 | R34: =SUM(N34:Q34) -> 0 | S34: =(R34/($R$61-$R$60))*SUM($R$64:$R$69,$R$71:$R$72,$R$74,$R$76,$R$78,$R$60)+R34 -> #DIV/0! | T34: =S34/G34 -> #DIV/0!
A35: 27 | I35: ='summary sheet'!$E$2 -> 120 | J35: =SUM(H35*I35)*G35 -> 0 | K35: 0 | L35: 0 | M35: 0 | N35: =J35 -> 0 | O35: =SUM(G35)*K35 -> 0 | P35: =SUM(L35) -> 0 | Q35: =M35 -> 0 | R35: =SUM(N35:Q35) -> 0 | S35: =(R35/($R$61-$R$60))*SUM($R$64:$R$69,$R$71:$R$72,$R$74,$R$76,$R$78,$R$60)+R35 -> #DIV/0! | T35: =S35/G35 -> #DIV/0!
A36: 28 | I36: ='summary sheet'!$E$2 -> 120 | J36: =SUM(H36*I36)*G36 -> 0 | K36: 0 | L36: 0 | M36: 0 | N36: =J36 -> 0 | O36: =SUM(G36)*K36 -> 0 | P36: =SUM(L36) -> 0 | Q36: =M36 -> 0 | R36: =SUM(N36:Q36) -> 0 | S36: =(R36/($R$61-$R$60))*SUM($R$64:$R$69,$R$71:$R$72,$R$74,$R$76,$R$78,$R$60)+R36 -> #DIV/0! | T36: =S36/G36 -> #DIV/0!
A37: 29 | I37: ='summary sheet'!$E$2 -> 120 | J37: =SUM(H37*I37)*G37 -> 0 | K37: 0 | L37: 0 | M37: 0 | N37: =J37 -> 0 | O37: =SUM(G37)*K37 -> 0 | P37: =SUM(L37) -> 0 | Q37: =M37 -> 0 | R37: =SUM(N37:Q37) -> 0 | S37: =(R37/($R$61-$R$60))*SUM($R$64:$R$69,$R$71:$R$72,$R$74,$R$76,$R$78,$R$60)+R37 -> #DIV/0! | T37: =S37/G37 -> #DIV/0!
... A55: 47 | I55: ='summary sheet'!$E$2 -> 120 | J55: =SUM(H55*I55)*G55 -> 0 | K55: 0 | L55: 0 | M55: 0 | N55: =J55 -> 0 | O55: =SUM(G55)*K55 -> 0 | P55: =SUM(L55) -> 0 | Q55: =M55 -> 0 | R55: =SUM(N55:Q55) -> 0 | S55: =(R55/($R$61-$R$60))*SUM($R$64:$R$69,$R$71:$R$72,$R$74,$R$76,$R$78,$R$60)+R55 -> #DIV/0! | T55: =S55/G55 -> #DIV/0!
A56: 48 | I56: ='summary sheet'!$E$2 -> 120 | J56: =SUM(I56*H56)*G56 -> 0 | K56: 0 | L56: 0 | M56: 0 | N56: =J56 -> 0 | O56: =SUM(G56)*K56 -> 0 | P56: =SUM(L56) -> 0 | Q56: =SUM(G56)*M56 -> 0 | R56: =SUM(N56:Q56) -> 0 | S56: =(R56/($R$61-$R$60))*SUM($R$64:$R$69,$R$71:$R$72,$R$74,$R$76,$R$78,$R$60)+R56 -> #DIV/0! | T56: =S56/G56 -> #DIV/0!
A57: 49 | I57: ='summary sheet'!$E$2 -> 120 | J57: =SUM(I57*H57)*G57 -> 0 | K57: 0 | L57: 0 | M57: 0 | N57: =J57 -> 0 | O57: =SUM(G57)*K57 -> 0 | P57: =SUM(L57) -> 0 | Q57: =SUM(G57)*M57 -> 0 | R57: =SUM(N57:Q57) -> 0 | S57: =(R57/($R$61-$R$60))*SUM($R$64:$R$69,$R$71:$R$72,$R$74,$R$76,$R$78,$R$60)+R57 -> #DIV/0! | T57: =S57/G57 -> #DIV/0!
A58: 50 | I58: ='summary sheet'!$E$2 -> 120 | J58: =SUM(I58*H58)*G58 -> 0 | K58: 0 | L58: 0 | M58: 0 | N58: =J58 -> 0 | O58: =SUM(G58)*K58 -> 0 | P58: =SUM(L58) -> 0 | Q58: =SUM(G58)*M58 -> 0 | R58: =SUM(N58:Q58) -> 0 | S58: =(R58/($R$61-$R$60))*SUM($R$64:$R$69,$R$71:$R$72,$R$74,$R$76,$R$78,$R$60)+R58 -> #DIV/0! | T58: =S58/G58 -> #DIV/0!
A59: SUBTOTAL | N59: =SUM(N9:N58) -> 0 | O59: =SUM(O9:O58) -> 0 | P59: =SUM(P9:P58) -> 0 | Q59: =SUM(Q9:Q58) -> 0 | R59: =SUM(N59:Q59) -> 0 | S59: =SUM(S9:S58) -> #DIV/0! | U59: =SUM(R9:R58)-R59 -> 0
A60: TAX | R60: =SUM(O59+P59)*U60 -> 0 | U60: ='summary sheet'!E1 -> 0.0975
A61: CATEGORY SUBTOTAL | R61: =SUM(R59:R60) -> 0
...

Sheet Lockers
A1: ='summary sheet'!A1 -> PROJECT:
A2: ='summary sheet'!A2:A2 -> SHIP TO:
A3: {=CONCATENATE("SCOPE: ",MID(CELL("filename",A1),FIND("]",CELL("filename",A1))+1,255))} -> SCOPE: Lockers
A4: ='summary sheet'!A4 -> BID INFO:
A5: ='summary sheet'!A5 -> 45940.587
J6: * * * * * * * * * * * UNIT COST * * * * * * * * * * * * * * * | N6: * * * * * * * * * * * * * * TOTAL COST * * * * * * * * * * * * * * * * * * | U6: Remarks
B7: SPEC No. | C7: SPEC TITLE | D7: PLAN CALLOUT | E7: DESCRIPTION | F7: MODEL NUMBER | G7: ITEM QUANTITY | H7: LABOR FACTOR | I7: LABOR RATE | J7: LABOR | K7: MATERIAL | L7: FREIGHT | M7: SUB | N7: LABOR | O7: MATERIAL | P7: FREIGHT | Q7: SUB | R7: TOTAL | S7: BREAKOUT COST | T7: BREAKOUT UNIT PRICE
M8: CONTRACT | Q8: CONTRACT
A9: 1 | I9: ='summary sheet'!$E$2 -> 120 | J9: =SUM(I9*H9)*G9 -> 0 | K9: 0 | L9: 0 | M9: 0 | N9: =J9 -> 0 | O9: =SUM(G9)*K9 -> 0 | P9: =SUM(L9) -> 0 | Q9: =SUM(G9)*M9 -> 0 | R9: =SUM(N9:Q9) -> 0 | S9: =(R9/($R$61-$R$60))*SUM($R$64:$R$69,$R$71:$R$72,$R$74,$R$76,$R$78,$R$60)+R9 -> #DIV/0! | T9: =S9/G9 -> #DIV/0!
A10: 2 | I10: ='summary sheet'!$E$2 -> 120 | J10: =SUM(I10*H10)*G10 -> 0 | K10: 0 | L10: 0 | M10: 0 | N10: =J10 -> 0 | O10: =SUM(G10)*K10 -> 0 | P10: =SUM(L10) -> 0 | Q10: =SUM(G10)*M10 -> 0 | R10: =SUM(N10:Q10) -> 0 | S10: =(R10/($R$61-$R$60))*SUM($R$64:$R$69,$R$71:$R$72,$R$74,$R$76,$R$78,$R$60)+R10 -> #DIV/0! | T10: =S10/G10 -> #DIV/0!
A11: 3 | I11: ='summary sheet'!$E$2 -> 120 | J11: =SUM(I11*H11)*G11 -> 0 | K11: 0 | L11: 0 | M11: 0 | N11: =J11 -> 0 | O11: =SUM(G11)*K11 -> 0 | P11: =SUM(L11) -> 0 | Q11: =SUM(G11)*M11 -> 0 | R11: =SUM(N11:Q11) -> 0 | S11: =(R11/($R$61-$R$60))*SUM($R$64:$R$69,$R$71:$R$72,$R$74,$R$76,$R$78,$R$60)+R11 -> #DIV/0! | T11: =S11/G11 -> #DIV/0!
A12: 4 | I12: ='summary sheet'!$E$2 -> 120 | J12: =SUM(I12*H12)*G12 -> 0 | K12: 0 | L12: 0 | M12: 0 | N12: =J12 -> 0 | O12: =SUM(G12)*K12 -> 0 | P12: =SUM(L12) -> 0 | Q12: =SUM(G12)*M12 -> 0 | R12: =SUM(N12:Q12) -> 0 | S12: =(R12/($R$61-$R$60))*SUM($R$64:$R$69,$R$71:$R$72,$R$74,$R$76,$R$78,$R$60)+R12 -> #DIV/0! | T12: =S12/G12 -> #DIV/0!
A13: 5 | I13: ='summary sheet'!$E$2 -> 120 | J13: =SUM(I13*H13)*G13 -> 0 | K13: 0 | L13: 0 | M13: 0 | N13: =J13 -> 0 | O13: =SUM(G13)*K13 -> 0 | P13: =SUM(L13) -> 0 | Q13: =SUM(G13)*M13 -> 0 | R13: =SUM(N13:Q13) -> 0 | S13: =(R13/($R$61-$R$60))*SUM($R$64:$R$69,$R$71:$R$72,$R$74,$R$76,$R$78,$R$60)+R13 -> #DIV/0! | T13: =S13/G13 -> #DIV/0!
A14: 6 | I14: ='summary sheet'!$E$2 -> 120 | J14: =SUM(I14*H14)*G14 -> 0 | K14: 0 | L14: 0 | M14: 0 | N14: =J14 -> 0 | O14: =SUM(G14)*K14 -> 0 | P14: =SUM(L14) -> 0 | Q14: =SUM(G14)*M14 -> 0 | R14: =SUM(N14:Q14) -> 0 | S14: =(R14/($R$61-$R$60))*SUM($R$64:$R$69,$R$71:$R$72,$R$74,$R$76,$R$78,$R$60)+R14 -> #DIV/0! | T14: =S14/G14 -> #DIV/0!
A15: 7 | I15: ='summary sheet'!$E$2 -> 120 | J15: =SUM(I15*H15)*G15 -> 0 | K15: 0 | L15: 0 | M15: 0 | N15: =J15 -> 0 | O15: =SUM(G15)*K15 -> 0 | P15: =SUM(L15) -> 0 | Q15: =SUM(G15)*M15 -> 0 | R15: =SUM(N15:Q15) -> 0 | S15: =(R15/($R$61-$R$60))*SUM($R$64:$R$69,$R$71:$R$72,$R$74,$R$76,$R$78,$R$60)+R15 -> #DIV/0! | T15: =S15/G15 -> #DIV/0!
A16: 8 | I16: ='summary sheet'!$E$2 -> 120 | J16: =SUM(I16*H16)*G16 -> 0 | K16: 0 | L16: 0 | M16: 0 | N16: =J16 -> 0 | O16: =SUM(G16)*K16 -> 0 | P16: =SUM(L16) -> 0 | Q16: =SUM(G16)*M16 -> 0 | R16: =SUM(N16:Q16) -> 0 | S16: =(R16/($R$61-$R$60))*SUM($R$64:$R$69,$R$71:$R$72,$R$74,$R$76,$R$78,$R$60)+R16 -> #DIV/0! | T16: =S16/G16 -> #DIV/0!
A17: 9 | I17: ='summary sheet'!$E$2 -> 120 | J17: =SUM(I17*H17)*G17 -> 0 | K17: 0 | L17: 0 | M17: 0 | N17: =J17 -> 0 | O17: =SUM(G17)*K17 -> 0 | P17: =SUM(L17) -> 0 | Q17: =SUM(G17)*M17 -> 0 | R17: =SUM(N17:Q17) -> 0 | S17: =(R17/($R$61-$R$60))*SUM($R$64:$R$69,$R$71:$R$72,$R$74,$R$76,$R$78,$R$60)+R17 -> #DIV/0! | T17: =S17/G17 -> #DIV/0!
A18: 10 | I18: ='summary sheet'!$E$2 -> 120 | J18: =SUM(I18*H18)*G18 -> 0 | K18: 0 | L18: 0 | M18: 0 | N18: =J18 -> 0 | O18: =SUM(G18)*K18 -> 0 | P18: =SUM(L18) -> 0 | Q18: =SUM(G18)*M18 -> 0 | R18: =SUM(N18:Q18) -> 0 | S18: =(R18/($R$61-$R$60))*SUM($R$64:$R$69,$R$71:$R$72,$R$74,$R$76,$R$78,$R$60)+R18 -> #DIV/0! | T18: =S18/G18 -> #DIV/0!
A19: 11 | I19: ='summary sheet'!$E$2 -> 120 | J19: =SUM(I19*H19)*G19 -> 0 | K19: 0 | L19: 0 | M19: 0 | N19: =J19 -> 0 | O19: =SUM(G19)*K19 -> 0 | P19: =SUM(L19) -> 0 | Q19: =SUM(G19)*M19 -> 0 | R19: =SUM(N19:Q19) -> 0 | S19: =(R19/($R$61-$R$60))*SUM($R$64:$R$69,$R$71:$R$72,$R$74,$R$76,$R$78,$R$60)+R19 -> #DIV/0! | T19: =S19/G19 -> #DIV/0!
A20: 12 | I20: ='summary sheet'!$E$2 -> 120 | J20: =SUM(I20*H20)*G20 -> 0 | K20: 0 | L20: 0 | M20: 0 | N20: =J20 -> 0 | O20: =SUM(G20)*K20 -> 0 | P20: =SUM(L20) -> 0 | Q20: =SUM(G20)*M20 -> 0 | R20: =SUM(N20:Q20) -> 0 | S20: =(R20/($R$61-$R$60))*SUM($R$64:$R$69,$R$71:$R$72,$R$74,$R$76,$R$78,$R$60)+R20 -> #DIV/0! | T20: =S20/G20 -> #DIV/0!
... A32: 24 | I32: ='summary sheet'!$E$2 -> 120 | J32: =SUM(I32*H32)*G32 -> 0 | K32: 0 | L32: 0 | M32: 0 | N32: =J32 -> 0 | O32: =SUM(G32)*K32 -> 0 | P32: =SUM(L32) -> 0 | Q32: =SUM(G32)*M32 -> 0 | R32: =SUM(N32:Q32) -> 0 | S32: =(R32/($R$61-$R$60))*SUM($R$64:$R$69,$R$71:$R$72,$R$74,$R$76,$R$78,$R$60)+R32 -> #DIV/0! | T32: =S32/G32 -> #DIV/0!
A33: 25 | I33: ='summary sheet'!$E$2 -> 120 | J33: =SUM(H33*I33)*G33 -> 0 | K33: 0 | L33: 0 | M33: 0 | N33: =J33 -> 0 | O33: =SUM(G33)*K33 -> 0 | P33: =SUM(L33) -> 0 | Q33: =M33 -> 0 | R33: =SUM(N33:Q33) -> 0 | S33: =(R33/($R$61-$R$60))*SUM($R$64:$R$69,$R$71:$R$72,$R$74,$R$76,$R$78,$R$60)+R33 -> #DIV/0! | T33: =S33/G33 -> #DIV/0!
A34: 26 | I34: ='summary sheet'!$E$2 -> 120 | J34: =SUM(H34*I34)*G34 -> 0 | K34: 0 | L34: 0 | M34: 0 | N34: =J34 -> 0 | O34: =SUM(G34)*K34 -> 0 | P34: =SUM(L34) -> 0 | Q34: =M34 -> 0 | R34: =SUM(N34:Q34) -> 0 | S34: =(R34/($R$61-$R$60))*SUM($R$64:$R$69,$R$71:$R$72,$R$74,$R$76,$R$78,$R$60)+R34 -> #DIV/0! | T34: =S34/G34 -> #DIV/0!
A35: 27 | I35: ='summary sheet'!$E$2 -> 120 | J35: =SUM(H35*I35)*G35 -> 0 | K35: 0 | L35: 0 | M35: 0 | N35: =J35 -> 0 | O35: =SUM(G35)*K35 -> 0 | P35: =SUM(L35) -> 0 | Q35: =M35 -> 0 | R35: =SUM(N35:Q35) -> 0 | S35: =(R35/($R$61-$R$60))*SUM($R$64:$R$69,$R$71:$R$72,$R$74,$R$76,$R$78,$R$60)+R35 -> #DIV/0! | T35: =S35/G35 -> #DIV/0!
